Workbook
Name H_TEMA_NUEVO: Estrategia!$C$3
Name H_REPASO: Estrategia!$C$4
Name H_SIMULACRO: Estrategia!$C$5
Name DIAS_ESTUDIO: Progreso!$M$2:$M$5
Name INTERVALOS: Progreso!$M$9:$M$17
Name DIAS_SEMANA: Progreso!$O$2:$O$8
Name DESPLAZAMIENTO: Progreso!$P$2:$P$8
Name ESTADO_EXITO: Progreso!$AN$1
Name ESTADO_FALLO: Progreso!$AN$2
Name DIAS_POR_SEMANA: Progreso!$AN$4
Name VENTANA_PROXIMA: Progreso!$AN$5
Name HOY: Calendario!$B$2

Sheet Estrategia
B2: Columna 1 | C2: Horas
B3: Tema nuevo | C3: 5
B4: Repaso activo | C4: 2.5
B5: Simulacro escrito | C5: 2.5
A7: Tarea | B7: Semana 1 | C7: Semana 2 | D7: Semana 3 | E7: Semana 4 | F7: Semana 5 | G7: Semana 6 | H7: Semana 7 | I7: Semana 8 | K7: Resumen semanas 1 a 8
A8: Temas nuevos | B8: 3 | C8: 2 | D8: 1 | E8: 2 | F8: 1 | G8: 1 | H8: 1 | I8: 2 | K8: Temas estudiados | L8: =SUM(B8:I8)
A9: Repasos | B9: 2 | C9: 4 | D9: 6 | E9: 3 | F9: 6 | G9: 6 | H9: 6 | I9: 3 | K9: Repasos | L9: =SUM(B9:I9)
A10: Simulacros | B10: 0 | C10: 0 | D10: 0 | E10: 1 | F10: 0 | G10: 0 | H10: 0 | I10: 1 | K10: Simulacros | L10: =SUM(B10:I10)
A11: Horas | B11: =B8*H_TEMA_NUEVO+B9*H_REPASO+B10*H_SIMULACRO | C11: =C8*H_TEMA_NUEVO+C9*H_REPASO+C10*H_SIMULACRO | D11: =D8*H_TEMA_NUEVO+D9*H_REPASO+D10*H_SIMULACRO | E11: =E8*H_TEMA_NUEVO+E9*H_REPASO+E10*H_SIMULACRO | F11: =F8*H_TEMA_NUEVO+F9*H_REPASO+F10*H_SIMULACRO | G11: =G8*H_TEMA_NUEVO+G9*H_REPASO+G10*H_SIMULACRO | H11: =H8*H_TEMA_NUEVO+H9*H_REPASO+H10*H_SIMULACRO | I11: =I8*H_TEMA_NUEVO+I9*H_REPASO+I10*H_SIMULACRO
A13: Tarea | B13: Semana 9 | C13: Semana 10 | D13: Semana 11 | E13: Semana 12 | F13: Semana 13 | G13: Semana 14 | H13: Semana 15 | I13: Semana 16 | K13: Resumen semanas 9 a 16
A14: Temas nuevos | B14: 1 | C14: 1 | D14: 1 | E14: 2 | F14: 1 | G14: 1 | H14: 1 | I14: 2 | K14: Temas estudiados | L14: =SUM(B14:I14)
A15: Repasos | B15: 6 | C15: 6 | D15: 6 | E15: 3 | F15: 6 | G15: 6 | H15: 6 | I15: 3 | K15: Repasos | L15: =SUM(B15:I15)
A16: Simulacros | B16: 0 | C16: 0 | D16: 0 | E16: 1 | F16: 0 | G16: 0 | H16: 0 | I16: 1 | K16: Simulacros | L16: =SUM(B16:I16)
A17: Horas | B17: =B14*H_TEMA_NUEVO+B15*H_REPASO+B16*H_SIMULACRO | C17: =C14*H_TEMA_NUEVO+C15*H_REPASO+C16*H_SIMULACRO | D17: =D14*H_TEMA_NUEVO+D15*H_REPASO+D16*H_SIMULACRO | E17: =E14*H_TEMA_NUEVO+E15*H_REPASO+E16*H_SIMULACRO | F17: =F14*H_TEMA_NUEVO+F15*H_REPASO+F16*H_SIMULACRO | G17: =G14*H_TEMA_NUEVO+G15*H_REPASO+G16*H_SIMULACRO | H17: =H14*H_TEMA_NUEVO+H15*H_REPASO+H16*H_SIMULACRO | I17: =I14*H_TEMA_NUEVO+I15*H_REPASO+I16*H_SIMULACRO
A19: Tarea | B19: Semana 17 | C19: Semana 18 | D19: Semana 19 | E19: Semana 20 | F19: Semana 21 | G19: Semana 22 | H19: Semana 23 | I19: Semana 24 | K19: Resumen semanas 17 a 24
A20: Temas nuevos | B20: 1 | C20: 1 | D20: 1 | E20: 2 | F20: 1 | G20: 1 | H20: 1 | I20: 2 | K20: Temas estudiados | L20: =SUM(B20:I20)
A21: Repasos | B21: 6 | C21: 6 | D21: 6 | E21: 3 | F21: 6 | G21: 6 | H21: 6 | I21: 3 | K21: Repasos | L21: =SUM(B21:I21)
A22: Simulacros | B22: 0 | C22: 0 | D22: 0 | E22: 1 | F22: 0 | G22: 0 | H22: 0 | I22: 1 | K22: Simulacros | L22: =SUM(B22:I22)
A23: Horas | B23: =B20*H_TEMA_NUEVO+B21*H_REPASO+B22*H_SIMULACRO | C23: =C20*H_TEMA_NUEVO+C21*H_REPASO+C22*H_SIMULACRO | D23: =D20*H_TEMA_NUEVO+D21*H_REPASO+D22*H_SIMULACRO | E23: =E20*H_TEMA_NUEVO+E21*H_REPASO+E22*H_SIMULACRO | F23: =F20*H_TEMA_NUEVO+F21*H_REPASO+F22*H_SIMULACRO | G23: =G20*H_TEMA_NUEVO+G21*H_REPASO+G22*H_SIMULACRO | H23: =H20*H_TEMA_NUEVO+H21*H_REPASO+H22*H_SIMULACRO | I23: =I20*H_TEMA_NUEVO+I21*H_REPASO+I22*H_SIMULACRO
A25: Tarea | B25: Semana 25 | C25: Semana 26 | D25: Semana 27 | E25: Semana 28 | F25: Semana 29 | G25: Semana 30 | K25: Resumen semanas 25 a 30
A26: Temas nuevos | B26: 1 | C26: 1 | D26: 1 | E26: 2 | F26: 1 | G26: 1 | H26: - | I26: - | K26: Temas estudiados | L26: =SUM(B26:G26)
A27: Repasos | B27: 6 | C27: 6 | D27: 6 | E27: 3 | F27: 6 | G27: 6 | H27: - | I27: - | K27: Repasos | L27: =SUM(B27:G27)
A28: Simulacros | B28: 0 | C28: 0 | D28: 0 | E28: 1 | F28: 0 | G28: 0 | H28: - | I28: - | K28: Simulacros | L28: =SUM(B28:G28)
A29: Horas | B29: =IF(B26="-","-",B26*H_TEMA_NUEVO+B27*H_REPASO+B28*H_SIMULACRO) | C29: =IF(C26="-","-",C26*H_TEMA_NUEVO+C27*H_REPASO+C28*H_SIMULACRO) | D29: =IF(D26="-","-",D26*H_TEMA_NUEVO+D27*H_REPASO+D28*H_SIMULACRO) | E29: =IF(E26="-","-",E26*H_TEMA_NUEVO+E27*H_REPASO+E28*H_SIMULACRO) | F29: =IF(F26="-","-",F26*H_TEMA_NUEVO+F27*H_REPASO+F28*H_SIMULACRO) | G29: =IF(G26="-","-",G26*H_TEMA_NUEVO+G27*H_REPASO+G28*H_SIMULACRO) | H29: =IF(H26="-","-",H26*H_TEMA_NUEVO+H27*H_REPASO+H28*H_SIMULACRO) | I29: =IF(I26="-","-",I26*H_TEMA_NUEVO+I27*H_REPASO+I28*H_SIMULACRO)
A31: Tarea | B31: Semana 31 | C31: Semana 32 | D31: Semana 33 | E31: Semana 34 | G31: Resumen semanas 31 a 34
A32: Repasos | B32: 10 | C32: 10 | D32: 10 | E32: 10 | G32: Repasos | H32: =SUM(B32:E32)
A33: Simulacros | B33: 1 | C33: 1 | D33: 1 | E33: 1 | G33: Simulacros | H33: =SUM(B33:E33)
A34: Horas | B34: =B32*H_REPASO+B33*H_SIMULACRO | C34: =C32*H_REPASO+C33*H_SIMULACRO | D34: =D32*H_REPASO+D33*H_SIMULACRO | E34: =E32*H_REPASO+E33*H_SIMULACRO

Sheet Progreso
A1: Temas | B1: Sesión 1 | C1: Sesión 2 | D1: Sesión 3 | E1: Sesión 4 | F1: Sesión 5 | G1: Sesión 6 | H1: Sesión 7 | I1: Sesión 8 | J1: Sesión 9 | K1: Sesión 10 | M1: Días de estudio | O1: Día de la semana | P1: Días hasta el siguiente día hábil | R1: Semillas de Sesión 2 a 10 (sobrescriben la propuesta del motor) | AB1: Matriz espejo de estados por sesión (Éxito / Fallo / vacío) | AM1: Etiqueta de sesión superada | AN1: Éxito | AP1: Semana | AQ1: Inicio | AR1: Fin | AS1: Éxitos | AT1: Fallos | AU1: Tasa de éxito | AV1: Completadas | AW1: Acumulado | AX1: Media móvil 3 | AZ1: Espejo numérico de fechas (0 = sin fecha)
A2: Tema 1 | B2: 46174 | C2: =IF($B2="","",IF(R2<>"",R2,(B2+INDEX(INTERVALOS,COLUMN()-COLUMN($B$1)))+INDEX(DESPLAZAMIENTO,WEEKDAY(B2+INDEX(INTERVALOS,COLUMN()-COLUMN($B$1)),2)))) | D2: =IF($B2="","",IF(S2<>"",S2,(C2+INDEX(INTERVALOS,COLUMN()-COLUMN($B$1)))+INDEX(DESPLAZAMIENTO,WEEKDAY(C2+INDEX(INTERVALOS,COLUMN()-COLUMN($B$1)),2)))) | E2: =IF($B2="","",IF(T2<>"",T2,(D2+INDEX(INTERVALOS,COLUMN()-COLUMN($B$1)))+INDEX(DESPLAZAMIENTO,WEEKDAY(D2+INDEX(INTERVALOS,COLUMN()-COLUMN($B$1)),2)))) | F2: =IF($B2="","",IF(U2<>"",U2,(E2+INDEX(INTERVALOS,COLUMN()-COLUMN($B$1)))+INDEX(DESPLAZAMIENTO,WEEKDAY(E2+INDEX(INTERVALOS,COLUMN()-COLUMN($B$1)),2)))) | G2: =IF($B2="","",IF(V2<>"",V2,(F2+INDEX(INTERVALOS,COLUMN()-COLUMN($B$1)))+INDEX(DESPLAZAMIENTO,WEEKDAY(F2+INDEX(INTERVALOS,COLUMN()-COLUMN($B$1)),2)))) | H2: =IF($B2="","",IF(W2<>"",W2,(G2+INDEX(INTERVALOS,COLUMN()-COLUMN($B$1)))+INDEX(DESPLAZAMIENTO,WEEKDAY(G2+INDEX(INTERVALOS,COLUMN()-COLUMN($B$1)),2)))) | I2: =IF($B2="","",IF(X2<>"",X2,(H2+INDEX(INTERVALOS,COLUMN()-COLUMN($B$1)))+INDEX(DESPLAZAMIENTO,WEEKDAY(H2+INDEX(INTERVALOS,COLUMN()-COLUMN($B$1)),2)))) | J2: =IF($B2="","",IF(Y2<>"",Y2,(I2+INDEX(INTERVALOS,COLUMN()-COLUMN($B$1)))+INDEX(DESPLAZAMIENTO,WEEKDAY(I2+INDEX(INTERVALOS,COLUMN()-COLUMN($B$1)),2)))) | K2: =IF($B2="","",IF(Z2<>"",Z2,(J2+INDEX(INTERVALOS,COLUMN()-COLUMN($B$1)))+INDEX(DESPLAZAMIENTO,WEEKDAY(J2+INDEX(INTERVALOS,COLUMN()-COLUMN($B$1)),2)))) | M2: Lunes | O2: Lunes | P2: =IF(COUNTIF(DIAS_ESTUDIO,$O$2)>0,0,IF(COUNTIF(DIAS_ESTUDIO,$O$3)>0,1,IF(COUNTIF(DIAS_ESTUDIO,$O$4)>0,2,IF(COUNTIF(DIAS_ESTUDIO,$O$5)>0,3,IF(COUNTIF(DIAS_ESTUDIO,$O$6)>0,4,IF(COUNTIF(DIAS_ESTUDIO,$O$7)>0,5,IF(COUNTIF(DIAS_ESTUDIO,$O$8)>0,6,0))))))) | R2: 46176 | S2: 46182 | T2: 46193 | AM2: Etiqueta de sesión fallida | AN2: Fallo | AP2: 1 | AQ2: =IF($AN$3="","",$AN$3+(AP2-1)*DIAS_POR_SEMANA) | AR2: =IF(AQ2="","",AQ2+DIAS_POR_SEMANA-1) | AS2: =IF(AQ2="",0,SUMPRODUCT(($AB$2:$AK$41=ESTADO_EXITO)*($AZ$2:$BI$41>=AQ2)*($AZ$2:$BI$41<=AR2))) | AT2: =IF(AQ2="",0,SUMPRODUCT(($AB$2:$AK$41=ESTADO_FALLO)*($AZ$2:$BI$41>=AQ2)*($AZ$2:$BI$41<=AR2))) | AU2: =IF(AS2+AT2=0,"",AS2/(AS2+AT2)) | AV2: =AS2+AT2 | AW2: =SUM($AV$2:AV2) | AZ2: =IF(B2="",0,B2) | BA2: =IF(C2="",0,C2) | BB2: =IF(D2="",0,D2) | BC2: =IF(E2="",0,E2) | BD2: =IF(F2="",0,F2) | BE2: =IF(G2="",0,G2) | BF2: =IF(H2="",0,H2) | BG2: =IF(I2="",0,I2) | ... BI2: =IF(K2="",0,K2)
A3: Tema 2 | B3: 46177 | C3: =IF($B3="","",IF(R3<>"",R3,(B3+INDEX(INTERVALOS,COLUMN()-COLUMN($B$1)))+INDEX(DESPLAZAMIENTO,WEEKDAY(B3+INDEX(INTERVALOS,COLUMN()-COLUMN($B$1)),2)))) | D3: =IF($B3="","",IF(S3<>"",S3,(C3+INDEX(INTERVALOS,COLUMN()-COLUMN($B$1)))+INDEX(DESPLAZAMIENTO,WEEKDAY(C3+INDEX(INTERVALOS,COLUMN()-COLUMN($B$1)),2)))) | E3: =IF($B3="","",IF(T3<>"",T3,(D3+INDEX(INTERVALOS,COLUMN()-COLUMN($B$1)))+INDEX(DESPLAZAMIENTO,WEEKDAY(D3+INDEX(INTERVALOS,COLUMN()-COLUMN($B$1)),2)))) | F3: =IF($B3="","",IF(U3<>"",U3,(E3+INDEX(INTERVALOS,COLUMN()-COLUMN($B$1)))+INDEX(DESPLAZAMIENTO,WEEKDAY(E3+INDEX(INTERVALOS,COLUMN()-COLUMN($B$1)),2)))) | G3: =IF($B3="","",IF(V3<>"",V3,(F3+INDEX(INTERVALOS,COLUMN()-COLUMN($B$1)))+INDEX(DESPLAZAMIENTO,WEEKDAY(F3+INDEX(INTERVALOS,COLUMN()-COLUMN($B$1)),2)))) | H3: =IF($B3="","",IF(W3<>"",W3,(G3+INDEX(INTERVALOS,COLUMN()-COLUMN($B$1)))+INDEX(DESPLAZAMIENTO,WEEKDAY(G3+INDEX(INTERVALOS,COLUMN()-COLUMN($B$1)),2)))) | I3: =IF($B3="","",IF(X3<>"",X3,(H3+INDEX(INTERVALOS,COLUMN()-COLUMN($B$1)))+INDEX(DESPLAZAMIENTO,WEEKDAY(H3+INDEX(INTERVALOS,COLUMN()-COLUMN($B$1)),2)))) | J3: =IF($B3="","",IF(Y3<>"",Y3,(I3+INDEX(INTERVALOS,COLUMN()-COLUMN($B$1)))+INDEX(DESPLAZAMIENTO,WEEKDAY(I3+INDEX(INTERVALOS,COLUMN()-COLUMN($B$1)),2)))) | K3: =IF($B3="","",IF(Z3<>"",Z3,(J3+INDEX(INTERVALOS,COLUMN()-COLUMN($B$1)))+INDEX(DESPLAZAMIENTO,WEEKDAY(J3+INDEX(INTERVALOS,COLUMN()-COLUMN($B$1)),2)))) | M3: Martes | O3: Martes | P3: =IF(COUNTIF(DIAS_ESTUDIO,$O$3)>0,0,IF(COUNTIF(DIAS_ESTUDIO,$O$4)>0,1,IF(COUNTIF(DIAS_ESTUDIO,$O$5)>0,2,IF(COUNTIF(DIAS_ESTUDIO,$O$6)>0,3,IF(COUNTIF(DIAS_ESTUDIO,$O$7)>0,4,IF(COUNTIF(DIAS_ESTUDIO,$O$8)>0,5,IF(COUNTIF(DIAS_ESTUDIO,$O$2)>0,6,0))))))) | R3: 46179 | S3: 46185 | T3: 46193 | AM3: Lunes de la primera sesión | AN3: =IF(MIN($B$2:$K$41)=0,"",MIN($B$2:$K$41)-WEEKDAY(MIN($B$2:$K$41),2)+1) | AP3: 2 | AQ3: =IF($AN$3="","",$AN$3+(AP3-1)*DIAS_POR_SEMANA) | AR3: =IF(AQ3="","",AQ3+DIAS_POR_SEMANA-1) | AS3: =IF(AQ3="",0,SUMPRODUCT(($AB$2:$AK$41=ESTADO_EXITO)*($AZ$2:$BI$41>=AQ3)*($AZ$2:$BI$41<=AR3))) | AT3: =IF(AQ3="",0,SUMPRODUCT(($AB$2:$AK$41=ESTADO_FALLO)*($AZ$2:$BI$41>=AQ3)*($AZ$2:$BI$41<=AR3))) | AU3: =IF(AS3+AT3=0,"",AS3/(AS3+AT3)) | AV3: =AS3+AT3 | AW3: =SUM($AV$2:AV3) | AZ3: =IF(B3="",0,B3) | BA3: =IF(C3="",0,C3) | BB3: =IF(D3="",0,D3) | BC3: =IF(E3="",0,E3) | BD3: =IF(F3="",0,F3) | BE3: =IF(G3="",0,G3) | BF3: =IF(H3="",0,H3) | BG3: =IF(I3="",0,I3) | ... BI3: =IF(K3="",0,K3)
A4: Tema 3 | B4: 46179 | C4: =IF($B4="","",IF(R4<>"",R4,(B4+INDEX(INTERVALOS,COLUMN()-COLUMN($B$1)))+INDEX(DESPLAZAMIENTO,WEEKDAY(B4+INDEX(INTERVALOS,COLUMN()-COLUMN($B$1)),2)))) | D4: =IF($B4="","",IF(S4<>"",S4,(C4+INDEX(INTERVALOS,COLUMN()-COLUMN($B$1)))+INDEX(DESPLAZAMIENTO,WEEKDAY(C4+INDEX(INTERVALOS,COLUMN()-COLUMN($B$1)),2)))) | E4: =IF($B4="","",IF(T4<>"",T4,(D4+INDEX(INTERVALOS,COLUMN()-COLUMN($B$1)))+INDEX(DESPLAZAMIENTO,WEEKDAY(D4+INDEX(INTERVALOS,COLUMN()-COLUMN($B$1)),2)))) | F4: =IF($B4="","",IF(U4<>"",U4,(E4+INDEX(INTERVALOS,COLUMN()-COLUMN($B$1)))+INDEX(DESPLAZAMIENTO,WEEKDAY(E4+INDEX(INTERVALOS,COLUMN()-COLUMN($B$1)),2)))) | G4: =IF($B4="","",IF(V4<>"",V4,(F4+INDEX(INTERVALOS,COLUMN()-COLUMN($B$1)))+INDEX(DESPLAZAMIENTO,WEEKDAY(F4+INDEX(INTERVALOS,COLUMN()-COLUMN($B$1)),2)))) | H4: =IF($B4="","",IF(W4<>"",W4,(G4+INDEX(INTERVALOS,COLUMN()-COLUMN($B$1)))+INDEX(DESPLAZAMIENTO,WEEKDAY(G4+INDEX(INTERVALOS,COLUMN()-COLUMN($B$1)),2)))) | I4: =IF($B4="","",IF(X4<>"",X4,(H4+INDEX(INTERVALOS,COLUMN()-COLUMN($B$1)))+INDEX(DESPLAZAMIENTO,WEEKDAY(H4+INDEX(INTERVALOS,COLUMN()-COLUMN($B$1)),2)))) | J4: =IF($B4="","",IF(Y4<>"",Y4,(I4+INDEX(INTERVALOS,COLUMN()-COLUMN($B$1)))+INDEX(DESPLAZAMIENTO,WEEKDAY(I4+INDEX(INTERVALOS,COLUMN()-COLUMN($B$1)),2)))) | K4: =IF($B4="","",IF(Z4<>"",Z4,(J4+INDEX(INTERVALOS,COLUMN()-COLUMN($B$1)))+INDEX(DESPLAZAMIENTO,WEEKDAY(J4+INDEX(INTERVALOS,COLUMN()-COLUMN($B$1)),2)))) | M4: Miércoles | O4: Miércoles | P4: =IF(COUNTIF(DIAS_ESTUDIO,$O$4)>0,0,IF(COUNTIF(DIAS_ESTUDIO,$O$5)>0,1,IF(COUNTIF(DIAS_ESTUDIO,$O$6)>0,2,IF(COUNTIF(DIAS_ESTUDIO,$O$7)>0,3,IF(COUNTIF(DIAS_ESTUDIO,$O$8)>0,4,IF(COUNTIF(DIAS_ESTUDIO,$O$2)>0,5,IF(COUNTIF(DIAS_ESTUDIO,$O$3)>0,6,0))))))) | R4: 46181 | S4: 46188 | T4: 46199 | AM4: Días por semana | AN4: 7 | AP4: 3 | AQ4: =IF($AN$3="","",$AN$3+(AP4-1)*DIAS_POR_SEMANA) | AR4: =IF(AQ4="","",AQ4+DIAS_POR_SEMANA-1) | AS4: =IF(AQ4="",0,SUMPRODUCT(($AB$2:$AK$41=ESTADO_EXITO)*($AZ$2:$BI$41>=AQ4)*($AZ$2:$BI$41<=AR4))) | AT4: =IF(AQ4="",0,SUMPRODUCT(($AB$2:$AK$41=ESTADO_FALLO)*($AZ$2:$BI$41>=AQ4)*($AZ$2:$BI$41<=AR4))) | AU4: =IF(AS4+AT4=0,"",AS4/(AS4+AT4)) | AV4: =AS4+AT4 | AW4: =SUM($AV$2:AV4) | AX4: =IF(COUNTIFS(AU2:AU4,">=0")=0,"",SUM(AU2:AU4)/COUNTIFS(AU2:AU4,">=0")) | AZ4: =IF(B4="",0,B4) | BA4: =IF(C4="",0,C4) | BB4: =IF(D4="",0,D4) | BC4: =IF(E4="",0,E4) | BD4: =IF(F4="",0,F4) | BE4: =IF(G4="",0,G4) | BF4: =IF(H4="",0,H4) | BG4: =IF(I4="",0,I4) | ... BI4: =IF(K4="",0,K4)
A5: Tema 4 | B5: 46183 | C5: =IF($B5="","",IF(R5<>"",R5,(B5+INDEX(INTERVALOS,COLUMN()-COLUMN($B$1)))+INDEX(DESPLAZAMIENTO,WEEKDAY(B5+INDEX(INTERVALOS,COLUMN()-COLUMN($B$1)),2)))) | D5: =IF($B5="","",IF(S5<>"",S5,(C5+INDEX(INTERVALOS,COLUMN()-COLUMN($B$1)))+INDEX(DESPLAZAMIENTO,WEEKDAY(C5+INDEX(INTERVALOS,COLUMN()-COLUMN($B$1)),2)))) | E5: =IF($B5="","",IF(T5<>"",T5,(D5+INDEX(INTERVALOS,COLUMN()-COLUMN($B$1)))+INDEX(DESPLAZAMIENTO,WEEKDAY(D5+INDEX(INTERVALOS,COLUMN()-COLUMN($B$1)),2)))) | F5: =IF($B5="","",IF(U5<>"",U5,(E5+INDEX(INTERVALOS,COLUMN()-COLUMN($B$1)))+INDEX(DESPLAZAMIENTO,WEEKDAY(E5+INDEX(INTERVALOS,COLUMN()-COLUMN($B$1)),2)))) | G5: =IF($B5="","",IF(V5<>"",V5,(F5+INDEX(INTERVALOS,COLUMN()-COLUMN($B$1)))+INDEX(DESPLAZAMIENTO,WEEKDAY(F5+INDEX(INTERVALOS,COLUMN()-COLUMN($B$1)),2)))) | H5: =IF($B5="","",IF(W5<>"",W5,(G5+INDEX(INTERVALOS,COLUMN()-COLUMN($B$1)))+INDEX(DESPLAZAMIENTO,WEEKDAY(G5+INDEX(INTERVALOS,COLUMN()-COLUMN($B$1)),2)))) | I5: =IF($B5="","",IF(X5<>"",X5,(H5+INDEX(INTERVALOS,COLUMN()-COLUMN($B$1)))+INDEX(DESPLAZAMIENTO,WEEKDAY(H5+INDEX(INTERVALOS,COLUMN()-COLUMN($B$1)),2)))) | J5: =IF($B5="","",IF(Y5<>"",Y5,(I5+INDEX(INTERVALOS,COLUMN()-COLUMN($B$1)))+INDEX(DESPLAZAMIENTO,WEEKDAY(I5+INDEX(INTERVALOS,COLUMN()-COLUMN($B$1)),2)))) | K5: =IF($B5="","",IF(Z5<>"",Z5,(J5+INDEX(INTERVALOS,COLUMN()-COLUMN($B$1)))+INDEX(DESPLAZAMIENTO,WEEKDAY(J5+INDEX(INTERVALOS,COLUMN()-COLUMN($B$1)),2)))) | M5: Jueves | O5: Jueves | P5: =IF(COUNTIF(DIAS_ESTUDIO,$O$5)>0,0,IF(COUNTIF(DIAS_ESTUDIO,$O$6)>0,1,IF(COUNTIF(DIAS_ESTUDIO,$O$7)>0,2,IF(COUNTIF(DIAS_ESTUDIO,$O$8)>0,3,IF(COUNTIF(DIAS_ESTUDIO,$O$2)>0,4,IF(COUNTIF(DIAS_ESTUDIO,$O$3)>0,5,IF(COUNTIF(DIAS_ESTUDIO,$O$4)>0,6,0))))))) | R5: 46186 | S5: 46193 | T5: 46200 | AM5: Ventana «próximos días» | AN5: 7 | AP5: 4 | AQ5: =IF($AN$3="","",$AN$3+(AP5-1)*DIAS_POR_SEMANA) | AR5: =IF(AQ5="","",AQ5+DIAS_POR_SEMANA-1) | AS5: =IF(AQ5="",0,SUMPRODUCT(($AB$2:$AK$41=ESTADO_EXITO)*($AZ$2:$BI$41>=AQ5)*($AZ$2:$BI$41<=AR5))) | AT5: =IF(AQ5="",0,SUMPRODUCT(($AB$2:$AK$41=ESTADO_FALLO)*($AZ$2:$BI$41>=AQ5)*($AZ$2:$BI$41<=AR5))) | AU5: =IF(AS5+AT5=0,"",AS5/(AS5+AT5)) | AV5: =AS5+AT5 | AW5: =SUM($AV$2:AV5) | AX5: =IF(COUNTIFS(AU3:AU5,">=0")=0,"",SUM(AU3:AU5)/COUNTIFS(AU3:AU5,">=0")) | AZ5: =IF(B5="",0,B5) | BA5: =IF(C5="",0,C5) | BB5: =IF(D5="",0,D5) | BC5: =IF(E5="",0,E5) | BD5: =IF(F5="",0,F5) | BE5: =IF(G5="",0,G5) | BF5: =IF(H5="",0,H5) | BG5: =IF(I5="",0,I5) | ... BI5: =IF(K5="",0,K5)
A6: Tema 5 | B6: 46186 | C6: =IF($B6="","",IF(R6<>"",R6,(B6+INDEX(INTERVALOS,COLUMN()-COLUMN($B$1)))+INDEX(DESPLAZAMIENTO,WEEKDAY(B6+INDEX(INTERVALOS,COLUMN()-COLUMN($B$1)),2)))) | D6: =IF($B6="","",IF(S6<>"",S6,(C6+INDEX(INTERVALOS,COLUMN()-COLUMN($B$1)))+INDEX(DESPLAZAMIENTO,WEEKDAY(C6+INDEX(INTERVALOS,COLUMN()-COLUMN($B$1)),2)))) | E6: =IF($B6="","",IF(T6<>"",T6,(D6+INDEX(INTERVALOS,COLUMN()-COLUMN($B$1)))+INDEX(DESPLAZAMIENTO,WEEKDAY(D6+INDEX(INTERVALOS,COLUMN()-COLUMN($B$1)),2)))) | F6: =IF($B6="","",IF(U6<>"",U6,(E6+INDEX(INTERVALOS,COLUMN()-COLUMN($B$1)))+INDEX(DESPLAZAMIENTO,WEEKDAY(E6+INDEX(INTERVALOS,COLUMN()-COLUMN($B$1)),2)))) | G6: =IF($B6="","",IF(V6<>"",V6,(F6+INDEX(INTERVALOS,COLUMN()-COLUMN($B$1)))+INDEX(DESPLAZAMIENTO,WEEKDAY(F6+INDEX(INTERVALOS,COLUMN()-COLUMN($B$1)),2)))) | H6: =IF($B6="","",IF(W6<>"",W6,(G6+INDEX(INTERVALOS,COLUMN()-COLUMN($B$1)))+INDEX(DESPLAZAMIENTO,WEEKDAY(G6+INDEX(INTERVALOS,COLUMN()-COLUMN($B$1)),2)))) | I6: =IF($B6="","",IF(X6<>"",X6,(H6+INDEX(INTERVALOS,COLUMN()-COLUMN($B$1)))+INDEX(DESPLAZAMIENTO,WEEKDAY(H6+INDEX(INTERVALOS,COLUMN()-COLUMN($B$1)),2)))) | J6: =IF($B6="","",IF(Y6<>"",Y6,(I6+INDEX(INTERVALOS,COLUMN()-COLUMN($B$1)))+INDEX(DESPLAZAMIENTO,WEEKDAY(I6+INDEX(INTERVALOS,COLUMN()-COLUMN($B$1)),2)))) | K6: =IF($B6="","",IF(Z6<>"",Z6,(J6+INDEX(INTERVALOS,COLUMN()-COLUMN($B$1)))+INDEX(DESPLAZAMIENTO,WEEKDAY(J6+INDEX(INTERVALOS,COLUMN()-COLUMN($B$1)),2)))) | O6: Viernes | P6: =IF(COUNTIF(DIAS_ESTUDIO,$O$6)>0,0,IF(COUNTIF(DIAS_ESTUDIO,$O$7)>0,1,IF(COUNTIF(DIAS_ESTUDIO,$O$8)>0,2,IF(COUNTIF(DIAS_ESTUDIO,$O$2)>0,3,IF(COUNTIF(DIAS_ESTUDIO,$O$3)>0,4,IF(COUNTIF(DIAS_ESTUDIO,$O$4)>0,5,IF(COUNTIF(DIAS_ESTUDIO,$O$5)>0,6,0))))))) | R6: 46189 | S6: 46197 | T6: 46207 | AP6: 5 | AQ6: =IF($AN$3="","",$AN$3+(AP6-1)*DIAS_POR_SEMANA) | AR6: =IF(AQ6="","",AQ6+DIAS_POR_SEMANA-1) | AS6: =IF(AQ6="",0,SUMPRODUCT(($AB$2:$AK$41=ESTADO_EXITO)*($AZ$2:$BI$41>=AQ6)*($AZ$2:$BI$41<=AR6))) | AT6: =IF(AQ6="",0,SUMPRODUCT(($AB$2:$AK$41=ESTADO_FALLO)*($AZ$2:$BI$41>=AQ6)*($AZ$2:$BI$41<=AR6))) | AU6: =IF(AS6+AT6=0,"",AS6/(AS6+AT6)) | AV6: =AS6+AT6 | AW6: =SUM($AV$2:AV6) | AX6: =IF(COUNTIFS(AU4:AU6,">=0")=0,"",SUM(AU4:AU6)/COUNTIFS(AU4:AU6,">=0")) | AZ6: =IF(B6="",0,B6) | BA6: =IF(C6="",0,C6) | BB6: =IF(D6="",0,D6) | BC6: =IF(E6="",0,E6) | BD6: =IF(F6="",0,F6) | BE6: =IF(G6="",0,G6) | BF6: =IF(H6="",0,H6) | BG6: =IF(I6="",0,I6) | ... BI6: =IF(K6="",0,K6)
A7: Tema 6 | B7: 46190 | C7: =IF($B7="","",IF(R7<>"",R7,(B7+INDEX(INTERVALOS,COLUMN()-COLUMN($B$1)))+INDEX(DESPLAZAMIENTO,WEEKDAY(B7+INDEX(INTERVALOS,COLUMN()-COLUMN($B$1)),2)))) | D7: =IF($B7="","",IF(S7<>"",S7,(C7+INDEX(INTERVALOS,COLUMN()-COLUMN($B$1)))+INDEX(DESPLAZAMIENTO,WEEKDAY(C7+INDEX(INTERVALOS,COLUMN()-COLUMN($B$1)),2)))) | E7: =IF($B7="","",IF(T7<>"",T7,(D7+INDEX(INTERVALOS,COLUMN()-COLUMN($B$1)))+INDEX(DESPLAZAMIENTO,WEEKDAY(D7+INDEX(INTERVALOS,COLUMN()-COLUMN($B$1)),2)))) | F7: =IF($B7="","",IF(U7<>"",U7,(E7+INDEX(INTERVALOS,COLUMN()-COLUMN($B$1)))+INDEX(DESPLAZAMIENTO,WEEKDAY(E7+INDEX(INTERVALOS,COLUMN()-COLUMN($B$1)),2)))) | G7: =IF($B7="","",IF(V7<>"",V7,(F7+INDEX(INTERVALOS,COLUMN()-COLUMN($B$1)))+INDEX(DESPLAZAMIENTO,WEEKDAY(F7+INDEX(INTERVALOS,COLUMN()-COLUMN($B$1)),2)))) | H7: =IF($B7="","",IF(W7<>"",W7,(G7+INDEX(INTERVALOS,COLUMN()-COLUMN($B$1)))+INDEX(DESPLAZAMIENTO,WEEKDAY(G7+INDEX(INTERVALOS,COLUMN()-COLUMN($B$1)),2)))) | I7: =IF($B7="","",IF(X7<>"",X7,(H7+INDEX(INTERVALOS,COLUMN()-COLUMN($B$1)))+INDEX(DESPLAZAMIENTO,WEEKDAY(H7+INDEX(INTERVALOS,COLUMN()-COLUMN($B$1)),2)))) | J7: =IF($B7="","",IF(Y7<>"",Y7,(I7+INDEX(INTERVALOS,COLUMN()-COLUMN($B$1)))+INDEX(DESPLAZAMIENTO,WEEKDAY(I7+INDEX(INTERVALOS,COLUMN()-COLUMN($B$1)),2)))) | K7: =IF($B7="","",IF(Z7<>"",Z7,(J7+INDEX(INTERVALOS,COLUMN()-COLUMN($B$1)))+INDEX(DESPLAZAMIENTO,WEEKDAY(J7+INDEX(INTERVALOS,COLUMN()-COLUMN($B$1)),2)))) | O7: Sábado | P7: =IF(COUNTIF(DIAS_ESTUDIO,$O$7)>0,0,IF(COUNTIF(DIAS_ESTUDIO,$O$8)>0,1,IF(COUNTIF(DIAS_ESTUDIO,$O$2)>0,2,IF(COUNTIF(DIAS_ESTUDIO,$O$3)>0,3,IF(COUNTIF(DIAS_ESTUDIO,$O$4)>0,4,IF(COUNTIF(DIAS_ESTUDIO,$O$5)>0,5,IF(COUNTIF(DIAS_ESTUDIO,$O$6)>0,6,0))))))) | R7: 46192 | S7: 46200 | AP7: 6 | AQ7: =IF($AN$3="","",$AN$3+(AP7-1)*DIAS_POR_SEMANA) | AR7: =IF(AQ7="","",AQ7+DIAS_POR_SEMANA-1) | AS7: =IF(AQ7="",0,SUMPRODUCT(($AB$2:$AK$41=ESTADO_EXITO)*($AZ$2:$BI$41>=AQ7)*($AZ$2:$BI$41<=AR7))) | AT7: =IF(AQ7="",0,SUMPRODUCT(($AB$2:$AK$41=ESTADO_FALLO)*($AZ$2:$BI$41>=AQ7)*($AZ$2:$BI$41<=AR7))) | AU7: =IF(AS7+AT7=0,"",AS7/(AS7+AT7)) | AV7: =AS7+AT7 | AW7: =SUM($AV$2:AV7) | AX7: =IF(COUNTIFS(AU5:AU7,">=0")=0,"",SUM(AU5:AU7)/COUNTIFS(AU5:AU7,">=0")) | AZ7: =IF(B7="",0,B7) | BA7: =IF(C7="",0,C7) | BB7: =IF(D7="",0,D7) | BC7: =IF(E7="",0,E7) | BD7: =IF(F7="",0,F7) | BE7: =IF(G7="",0,G7) | BF7: =IF(H7="",0,H7) | BG7: =IF(I7="",0,I7) | ... BI7: =IF(K7="",0,K7)
A8: Tema 7 | B8: 46195 | C8: =IF($B8="","",IF(R8<>"",R8,(B8+INDEX(INTERVALOS,COLUMN()-COLUMN($B$1)))+INDEX(DESPLAZAMIENTO,WEEKDAY(B8+INDEX(INTERVALOS,COLUMN()-COLUMN($B$1)),2)))) | D8: =IF($B8="","",IF(S8<>"",S8,(C8+INDEX(INTERVALOS,COLUMN()-COLUMN($B$1)))+INDEX(DESPLAZAMIENTO,WEEKDAY(C8+INDEX(INTERVALOS,COLUMN()-COLUMN($B$1)),2)))) | E8: =IF($B8="","",IF(T8<>"",T8,(D8+INDEX(INTERVALOS,COLUMN()-COLUMN($B$1)))+INDEX(DESPLAZAMIENTO,WEEKDAY(D8+INDEX(INTERVALOS,COLUMN()-COLUMN($B$1)),2)))) | F8: =IF($B8="","",IF(U8<>"",U8,(E8+INDEX(INTERVALOS,COLUMN()-COLUMN($B$1)))+INDEX(DESPLAZAMIENTO,WEEKDAY(E8+INDEX(INTERVALOS,COLUMN()-COLUMN($B$1)),2)))) | G8: =IF($B8="","",IF(V8<>"",V8,(F8+INDEX(INTERVALOS,COLUMN()-COLUMN($B$1)))+INDEX(DESPLAZAMIENTO,WEEKDAY(F8+INDEX(INTERVALOS,COLUMN()-COLUMN($B$1)),2)))) | H8: =IF($B8="","",IF(W8<>"",W8,(G8+INDEX(INTERVALOS,COLUMN()-COLUMN($B$1)))+INDEX(DESPLAZAMIENTO,WEEKDAY(G8+INDEX(INTERVALOS,COLUMN()-COLUMN($B$1)),2)))) | I8: =IF($B8="","",IF(X8<>"",X8,(H8+INDEX(INTERVALOS,COLUMN()-COLUMN($B$1)))+INDEX(DESPLAZAMIENTO,WEEKDAY(H8+INDEX(INTERVALOS,COLUMN()-COLUMN($B$1)),2)))) | J8: =IF($B8="","",IF(Y8<>"",Y8,(I8+INDEX(INTERVALOS,COLUMN()-COLUMN($B$1)))+INDEX(DESPLAZAMIENTO,WEEKDAY(I8+INDEX(INTERVALOS,COLUMN()-COLUMN($B$1)),2)))) | K8: =IF($B8="","",IF(Z8<>"",Z8,(J8+INDEX(INTERVALOS,COLUMN()-COLUMN($B$1)))+INDEX(DESPLAZAMIENTO,WEEKDAY(J8+INDEX(INTERVALOS,COLUMN()-COLUMN($B$1)),2)))) | M8: Intervalos (días) | O8: Domingo | P8: =IF(COUNTIF(DIAS_ESTUDIO,$O$8)>0,0,IF(COUNTIF(DIAS_ESTUDIO,$O$2)>0,1,IF(COUNTIF(DIAS_ESTUDIO,$O$3)>0,2,IF(COUNTIF(DIAS_ESTUDIO,$O$4)>0,3,IF(COUNTIF(DIAS_ESTUDIO,$O$5)>0,4,IF(COUNTIF(DIAS_ESTUDIO,$O$6)>0,5,IF(COUNTIF(DIAS_ESTUDIO,$O$7)>0,6,0))))))) | R8: 46198 | S8: 46200 | AP8: 7 | AQ8: =IF($AN$3="","",$AN$3+(AP8-1)*DIAS_POR_SEMANA) | AR8: =IF(AQ8="","",AQ8+DIAS_POR_SEMANA-1) | AS8: =IF(AQ8="",0,SUMPRODUCT(($AB$2:$AK$41=ESTADO_EXITO)*($AZ$2:$BI$41>=AQ8)*($AZ$2:$BI$41<=AR8))) | AT8: =IF(AQ8="",0,SUMPRODUCT(($AB$2:$AK$41=ESTADO_FALLO)*($AZ$2:$BI$41>=AQ8)*($AZ$2:$BI$41<=AR8))) | AU8: =IF(AS8+AT8=0,"",AS8/(AS8+AT8)) | AV8: =AS8+AT8 | AW8: =SUM($AV$2:AV8) | AX8: =IF(COUNTIFS(AU6:AU8,">=0")=0,"",SUM(AU6:AU8)/COUNTIFS(AU6:AU8,">=0")) | AZ8: =IF(B8="",0,B8) | BA8: =IF(C8="",0,C8) | BB8: =IF(D8="",0,D8) | BC8: =IF(E8="",0,E8) | BD8: =IF(F8="",0,F8) | BE8: =IF(G8="",0,G8) | BF8: =IF(H8="",0,H8) | BG8: =IF(I8="",0,I8) | ... BI8: =IF(K8="",0,K8)
A9: Tema 8 | B9: 46202 | C9: =IF($B9="","",IF(R9<>"",R9,(B9+INDEX(INTERVALOS,COLUMN()-COLUMN($B$1)))+INDEX(DESPLAZAMIENTO,WEEKDAY(B9+INDEX(INTERVALOS,COLUMN()-COLUMN($B$1)),2)))) | D9: =IF($B9="","",IF(S9<>"",S9,(C9+INDEX(INTERVALOS,COLUMN()-COLUMN($B$1)))+INDEX(DESPLAZAMIENTO,WEEKDAY(C9+INDEX(INTERVALOS,COLUMN()-COLUMN($B$1)),2)))) | E9: =IF($B9="","",IF(T9<>"",T9,(D9+INDEX(INTERVALOS,COLUMN()-COLUMN($B$1)))+INDEX(DESPLAZAMIENTO,WEEKDAY(D9+INDEX(INTERVALOS,COLUMN()-COLUMN($B$1)),2)))) | F9: =IF($B9="","",IF(U9<>"",U9,(E9+INDEX(INTERVALOS,COLUMN()-COLUMN($B$1)))+INDEX(DESPLAZAMIENTO,WEEKDAY(E9+INDEX(INTERVALOS,COLUMN()-COLUMN($B$1)),2)))) | G9: =IF($B9="","",IF(V9<>"",V9,(F9+INDEX(INTERVALOS,COLUMN()-COLUMN($B$1)))+INDEX(DESPLAZAMIENTO,WEEKDAY(F9+INDEX(INTERVALOS,COLUMN()-COLUMN($B$1)),2)))) | H9: =IF($B9="","",IF(W9<>"",W9,(G9+INDEX(INTERVALOS,COLUMN()-COLUMN($B$1)))+INDEX(DESPLAZAMIENTO,WEEKDAY(G9+INDEX(INTERVALOS,COLUMN()-COLUMN($B$1)),2)))) | I9: =IF($B9="","",IF(X9<>"",X9,(H9+INDEX(INTERVALOS,COLUMN()-COLUMN($B$1)))+INDEX(DESPLAZAMIENTO,WEEKDAY(H9+INDEX(INTERVALOS,COLUMN()-COLUMN($B$1)),2)))) | J9: =IF($B9="","",IF(Y9<>"",Y9,(I9+INDEX(INTERVALOS,COLUMN()-COLUMN($B$1)))+INDEX(DESPLAZAMIENTO,WEEKDAY(I9+INDEX(INTERVALOS,COLUMN()-COLUMN($B$1)),2)))) | K9: =IF($B9="","",IF(Z9<>"",Z9,(J9+INDEX(INTERVALOS,COLUMN()-COLUMN($B$1)))+INDEX(DESPLAZAMIENTO,WEEKDAY(J9+INDEX(INTERVALOS,COLUMN()-COLUMN($B$1)),2)))) | M9: 2 | R9: 46204 | AP9: 8 | AQ9: =IF($AN$3="","",$AN$3+(AP9-1)*DIAS_POR_SEMANA) | AR9: =IF(AQ9="","",AQ9+DIAS_POR_SEMANA-1) | AS9: =IF(AQ9="",0,SUMPRODUCT(($AB$2:$AK$41=ESTADO_EXITO)*($AZ$2:$BI$41>=AQ9)*($AZ$2:$BI$41<=AR9))) | AT9: =IF(AQ9="",0,SUMPRODUCT(($AB$2:$AK$41=ESTADO_FALLO)*($AZ$2:$BI$41>=AQ9)*($AZ$2:$BI$41<=AR9))) | AU9: =IF(AS9+AT9=0,"",AS9/(AS9+AT9)) | AV9: =AS9+AT9 | AW9: =SUM($AV$2:AV9) | AX9: =IF(COUNTIFS(AU7:AU9,">=0")=0,"",SUM(AU7:AU9)/COUNTIFS(AU7:AU9,">=0")) | AZ9: =IF(B9="",0,B9) | BA9: =IF(C9="",0,C9) | BB9: =IF(D9="",0,D9) | BC9: =IF(E9="",0,E9) | BD9: =IF(F9="",0,F9) | BE9: =IF(G9="",0,G9) | BF9: =IF(H9="",0,H9) | BG9: =IF(I9="",0,I9) | ... BI9: =IF(K9="",0,K9)
A10: Tema 9 | B10: 46205 | C10: =IF($B10="","",IF(R10<>"",R10,(B10+INDEX(INTERVALOS,COLUMN()-COLUMN($B$1)))+INDEX(DESPLAZAMIENTO,WEEKDAY(B10+INDEX(INTERVALOS,COLUMN()-COLUMN($B$1)),2)))) | D10: =IF($B10="","",IF(S10<>"",S10,(C10+INDEX(INTERVALOS,COLUMN()-COLUMN($B$1)))+INDEX(DESPLAZAMIENTO,WEEKDAY(C10+INDEX(INTERVALOS,COLUMN()-COLUMN($B$1)),2)))) | E10: =IF($B10="","",IF(T10<>"",T10,(D10+INDEX(INTERVALOS,COLUMN()-COLUMN($B$1)))+INDEX(DESPLAZAMIENTO,WEEKDAY(D10+INDEX(INTERVALOS,COLUMN()-COLUMN($B$1)),2)))) | F10: =IF($B10="","",IF(U10<>"",U10,(E10+INDEX(INTERVALOS,COLUMN()-COLUMN($B$1)))+INDEX(DESPLAZAMIENTO,WEEKDAY(E10+INDEX(INTERVALOS,COLUMN()-COLUMN($B$1)),2)))) | G10: =IF($B10="","",IF(V10<>"",V10,(F10+INDEX(INTERVALOS,COLUMN()-COLUMN($B$1)))+INDEX(DESPLAZAMIENTO,WEEKDAY(F10+INDEX(INTERVALOS,COLUMN()-COLUMN($B$1)),2)))) | H10: =IF($B10="","",IF(W10<>"",W10,(G10+INDEX(INTERVALOS,COLUMN()-COLUMN($B$1)))+INDEX(DESPLAZAMIENTO,WEEKDAY(G10+INDEX(INTERVALOS,COLUMN()-COLUMN($B$1)),2)))) | I10: =IF($B10="","",IF(X10<>"",X10,(H10+INDEX(INTERVALOS,COLUMN()-COLUMN($B$1)))+INDEX(DESPLAZAMIENTO,WEEKDAY(H10+INDEX(INTERVALOS,COLUMN()-COLUMN($B$1)),2)))) | J10: =IF($B10="","",IF(Y10<>"",Y10,(I10+INDEX(INTERVALOS,COLUMN()-COLUMN($B$1)))+INDEX(DESPLAZAMIENTO,WEEKDAY(I10+INDEX(INTERVALOS,COLUMN()-COLUMN($B$1)),2)))) | K10: =IF($B10="","",IF(Z10<>"",Z10,(J10+INDEX(INTERVALOS,COLUMN()-COLUMN($B$1)))+INDEX(DESPLAZAMIENTO,WEEKDAY(J10+INDEX(INTERVALOS,COLUMN()-COLUMN($B$1)),2)))) | M10: 7 | R10: 46207 | AP10: 9 | AQ10: =IF($AN$3="","",$AN$3+(AP10-1)*DIAS_POR_SEMANA) | AR10: =IF(AQ10="","",AQ10+DIAS_POR_SEMANA-1) | AS10: =IF(AQ10="",0,SUMPRODUCT(($AB$2:$AK$41=ESTADO_EXITO)*($AZ$2:$BI$41>=AQ10)*($AZ$2:$BI$41<=AR10))) | AT10: =IF(AQ10="",0,SUMPRODUCT(($AB$2:$AK$41=ESTADO_FALLO)*($AZ$2:$BI$41>=AQ10)*($AZ$2:$BI$41<=AR10))) | AU10: =IF(AS10+AT10=0,"",AS10/(AS10+AT10)) | AV10: =AS10+AT10 | AW10: =SUM($AV$2:AV10) | AX10: =IF(COUNTIFS(AU8:AU10,">=0")=0,"",SUM(AU8:AU10)/COUNTIFS(AU8:AU10,">=0")) | AZ10: =IF(B10="",0,B10) | BA10: =IF(C10="",0,C10) | BB10: =IF(D10="",0,D10) | BC10: =IF(E10="",0,E10) | BD10: =IF(F10="",0,F10) | BE10: =IF(G10="",0,G10) | BF10: =IF(H10="",0,H10) | BG10: =IF(I10="",0,I10) | ... BI10: =IF(K10="",0,K10)
A11: Tema 10 | C11: =IF($B11="","",IF(R11<>"",R11,(B11+INDEX(INTERVALOS,COLUMN()-COLUMN($B$1)))+INDEX(DESPLAZAMIENTO,WEEKDAY(B11+INDEX(INTERVALOS,COLUMN()-COLUMN($B$1)),2)))) | D11: =IF($B11="","",IF(S11<>"",S11,(C11+INDEX(INTERVALOS,COLUMN()-COLUMN($B$1)))+INDEX(DESPLAZAMIENTO,WEEKDAY(C11+INDEX(INTERVALOS,COLUMN()-COLUMN($B$1)),2)))) | E11: =IF($B11="","",IF(T11<>"",T11,(D11+INDEX(INTERVALOS,COLUMN()-COLUMN($B$1)))+INDEX(DESPLAZAMIENTO,WEEKDAY(D11+INDEX(INTERVALOS,COLUMN()-COLUMN($B$1)),2)))) | F11: =IF($B11="","",IF(U11<>"",U11,(E11+INDEX(INTERVALOS,COLUMN()-COLUMN($B$1)))+INDEX(DESPLAZAMIENTO,WEEKDAY(E11+INDEX(INTERVALOS,COLUMN()-COLUMN($B$1)),2)))) | G11: =IF($B11="","",IF(V11<>"",V11,(F11+INDEX(INTERVALOS,COLUMN()-COLUMN($B$1)))+INDEX(DESPLAZAMIENTO,WEEKDAY(F11+INDEX(INTERVALOS,COLUMN()-COLUMN($B$1)),2)))) | H11: =IF($B11="","",IF(W11<>"",W11,(G11+INDEX(INTERVALOS,COLUMN()-COLUMN($B$1)))+INDEX(DESPLAZAMIENTO,WEEKDAY(G11+INDEX(INTERVALOS,COLUMN()-COLUMN($B$1)),2)))) | I11: =IF($B11="","",IF(X11<>"",X11,(H11+INDEX(INTERVALOS,COLUMN()-COLUMN($B$1)))+INDEX(DESPLAZAMIENTO,WEEKDAY(H11+INDEX(INTERVALOS,COLUMN()-COLUMN($B$1)),2)))) | J11: =IF($B11="","",IF(Y11<>"",Y11,(I11+INDEX(INTERVALOS,COLUMN()-COLUMN($B$1)))+INDEX(DESPLAZAMIENTO,WEEKDAY(I11+INDEX(INTERVALOS,COLUMN()-COLUMN($B$1)),2)))) | K11: =IF($B11="","",IF(Z11<>"",Z11,(J11+INDEX(INTERVALOS,COLUMN()-COLUMN($B$1)))+INDEX(DESPLAZAMIENTO,WEEKDAY(J11+INDEX(INTERVALOS,COLUMN()-COLUMN($B$1)),2)))) | M11: 14 | AP11: 10 | AQ11: =IF($AN$3="","",$AN$3+(AP11-1)*DIAS_POR_SEMANA) | AR11: =IF(AQ11="","",AQ11+DIAS_POR_SEMANA-1) | AS11: =IF(AQ11="",0,SUMPRODUCT(($AB$2:$AK$41=ESTADO_EXITO)*($AZ$2:$BI$41>=AQ11)*($AZ$2:$BI$41<=AR11))) | AT11: =IF(AQ11="",0,SUMPRODUCT(($AB$2:$AK$41=ESTADO_FALLO)*($AZ$2:$BI$41>=AQ11)*($AZ$2:$BI$41<=AR11))) | AU11: =IF(AS11+AT11=0,"",AS11/(AS11+AT11)) | AV11: =AS11+AT11 | AW11: =SUM($AV$2:AV11) | AX11: =IF(COUNTIFS(AU9:AU11,">=0")=0,"",SUM(AU9:AU11)/COUNTIFS(AU9:AU11,">=0")) | AZ11: =IF(B11="",0,B11) | BA11: =IF(C11="",0,C11) | BB11: =IF(D11="",0,D11) | BC11: =IF(E11="",0,E11) | BD11: =IF(F11="",0,F11) | BE11: =IF(G11="",0,G11) | BF11: =IF(H11="",0,H11) | BG11: =IF(I11="",0,I11) | ... BI11: =IF(K11="",0,K11)
A12: Tema 11 | C12: =IF($B12="","",IF(R12<>"",R12,(B12+INDEX(INTERVALOS,COLUMN()-COLUMN($B$1)))+INDEX(DESPLAZAMIENTO,WEEKDAY(B12+INDEX(INTERVALOS,COLUMN()-COLUMN($B$1)),2)))) | D12: =IF($B12="","",IF(S12<>"",S12,(C12+INDEX(INTERVALOS,COLUMN()-COLUMN($B$1)))+INDEX(DESPLAZAMIENTO,WEEKDAY(C12+INDEX(INTERVALOS,COLUMN()-COLUMN($B$1)),2)))) | E12: =IF($B12="","",IF(T12<>"",T12,(D12+INDEX(INTERVALOS,COLUMN()-COLUMN($B$1)))+INDEX(DESPLAZAMIENTO,WEEKDAY(D12+INDEX(INTERVALOS,COLUMN()-COLUMN($B$1)),2)))) | F12: =IF($B12="","",IF(U12<>"",U12,(E12+INDEX(INTERVALOS,COLUMN()-COLUMN($B$1)))+INDEX(DESPLAZAMIENTO,WEEKDAY(E12+INDEX(INTERVALOS,COLUMN()-COLUMN($B$1)),2)))) | G12: =IF($B12="","",IF(V12<>"",V12,(F12+INDEX(INTERVALOS,COLUMN()-COLUMN($B$1)))+INDEX(DESPLAZAMIENTO,WEEKDAY(F12+INDEX(INTERVALOS,COLUMN()-COLUMN($B$1)),2)))) | H12: =IF($B12="","",IF(W12<>"",W12,(G12+INDEX(INTERVALOS,COLUMN()-COLUMN($B$1)))+INDEX(DESPLAZAMIENTO,WEEKDAY(G12+INDEX(INTERVALOS,COLUMN()-COLUMN($B$1)),2)))) | I12: =IF($B12="","",IF(X12<>"",X12,(H12+INDEX(INTERVALOS,COLUMN()-COLUMN($B$1)))+INDEX(DESPLAZAMIENTO,WEEKDAY(H12+INDEX(INTERVALOS,COLUMN()-COLUMN($B$1)),2)))) | J12: =IF($B12="","",IF(Y12<>"",Y12,(I12+INDEX(INTERVALOS,COLUMN()-COLUMN($B$1)))+INDEX(DESPLAZAMIENTO,WEEKDAY(I12+INDEX(INTERVALOS,COLUMN()-COLUMN($B$1)),2)))) | K12: =IF($B12="","",IF(Z12<>"",Z12,(J12+INDEX(INTERVALOS,COLUMN()-COLUMN($B$1)))+INDEX(DESPLAZAMIENTO,WEEKDAY(J12+INDEX(INTERVALOS,COLUMN()-COLUMN($B$1)),2)))) | M12: 30 | AP12: 11 | AQ12: =IF($AN$3="","",$AN$3+(AP12-1)*DIAS_POR_SEMANA) | AR12: =IF(AQ12="","",AQ12+DIAS_POR_SEMANA-1) | AS12: =IF(AQ12="",0,SUMPRODUCT(($AB$2:$AK$41=ESTADO_EXITO)*($AZ$2:$BI$41>=AQ12)*($AZ$2:$BI$41<=AR12))) | AT12: =IF(AQ12="",0,SUMPRODUCT(($AB$2:$AK$41=ESTADO_FALLO)*($AZ$2:$BI$41>=AQ12)*($AZ$2:$BI$41<=AR12))) | AU12: =IF(AS12+AT12=0,"",AS12/(AS12+AT12)) | AV12: =AS12+AT12 | AW12: =SUM($AV$2:AV12) | AX12: =IF(COUNTIFS(AU10:AU12,">=0")=0,"",SUM(AU10:AU12)/COUNTIFS(AU10:AU12,">=0")) | AZ12: =IF(B12="",0,B12) | BA12: =IF(C12="",0,C12) | BB12: =IF(D12="",0,D12) | BC12: =IF(E12="",0,E12) | BD12: =IF(F12="",0,F12) | BE12: =IF(G12="",0,G12) | BF12: =IF(H12="",0,H12) | BG12: =IF(I12="",0,I12) | ... BI12: =IF(K12="",0,K12)
A13: Tema 12 | C13: =IF($B13="","",IF(R13<>"",R13,(B13+INDEX(INTERVALOS,COLUMN()-COLUMN($B$1)))+INDEX(DESPLAZAMIENTO,WEEKDAY(B13+INDEX(INTERVALOS,COLUMN()-COLUMN($B$1)),2)))) | D13: =IF($B13="","",IF(S13<>"",S13,(C13+INDEX(INTERVALOS,COLUMN()-COLUMN($B$1)))+INDEX(DESPLAZAMIENTO,WEEKDAY(C13+INDEX(INTERVALOS,COLUMN()-COLUMN($B$1)),2)))) | E13: =IF($B13="","",IF(T13<>"",T13,(D13+INDEX(INTERVALOS,COLUMN()-COLUMN($B$1)))+INDEX(DESPLAZAMIENTO,WEEKDAY(D13+INDEX(INTERVALOS,COLUMN()-COLUMN($B$1)),2)))) | F13: =IF($B13="","",IF(U13<>"",U13,(E13+INDEX(INTERVALOS,COLUMN()-COLUMN($B$1)))+INDEX(DESPLAZAMIENTO,WEEKDAY(E13+INDEX(INTERVALOS,COLUMN()-COLUMN($B$1)),2)))) | G13: =IF($B13="","",IF(V13<>"",V13,(F13+INDEX(INTERVALOS,COLUMN()-COLUMN($B$1)))+INDEX(DESPLAZAMIENTO,WEEKDAY(F13+INDEX(INTERVALOS,COLUMN()-COLUMN($B$1)),2)))) | H13: =IF($B13="","",IF(W13<>"",W13,(G13+INDEX(INTERVALOS,COLUMN()-COLUMN($B$1)))+INDEX(DESPLAZAMIENTO,WEEKDAY(G13+INDEX(INTERVALOS,COLUMN()-COLUMN($B$1)),2)))) | I13: =IF($B13="","",IF(X13<>"",X13,(H13+INDEX(INTERVALOS,COLUMN()-COLUMN($B$1)))+INDEX(DESPLAZAMIENTO,WEEKDAY(H13+INDEX(INTERVALOS,COLUMN()-COLUMN($B$1)),2)))) | J13: =IF($B13="","",IF(Y13<>"",Y13,(I13+INDEX(INTERVALOS,COLUMN()-COLUMN($B$1)))+INDEX(DESPLAZAMIENTO,WEEKDAY(I13+INDEX(INTERVALOS,COLUMN()-COLUMN($B$1)),2)))) | K13: =IF($B13="","",IF(Z13<>"",Z13,(J13+INDEX(INTERVALOS,COLUMN()-COLUMN($B$1)))+INDEX(DESPLAZAMIENTO,WEEKDAY(J13+INDEX(INTERVALOS,COLUMN()-COLUMN($B$1)),2)))) | M13: 60 | AP13: 12 | AQ13: =IF($AN$3="","",$AN$3+(AP13-1)*DIAS_POR_SEMANA) | AR13: =IF(AQ13="","",AQ13+DIAS_POR_SEMANA-1) | AS13: =IF(AQ13="",0,SUMPRODUCT(($AB$2:$AK$41=ESTADO_EXITO)*($AZ$2:$BI$41>=AQ13)*($AZ$2:$BI$41<=AR13))) | AT13: =IF(AQ13="",0,SUMPRODUCT(($AB$2:$AK$41=ESTADO_FALLO)*($AZ$2:$BI$41>=AQ13)*($AZ$2:$BI$41<=AR13))) | AU13: =IF(AS13+AT13=0,"",AS13/(AS13+AT13)) | AV13: =AS13+AT13 | AW13: =SUM($AV$2:AV13) | AX13: =IF(COUNTIFS(AU11:AU13,">=0")=0,"",SUM(AU11:AU13)/COUNTIFS(AU11:AU13,">=0")) | AZ13: =IF(B13="",0,B13) | BA13: =IF(C13="",0,C13) | BB13: =IF(D13="",0,D13) | BC13: =IF(E13="",0,E13) | BD13: =IF(F13="",0,F13) | BE13: =IF(G13="",0,G13) | BF13: =IF(H13="",0,H13) | BG13: =IF(I13="",0,I13) | ... BI13: =IF(K13="",0,K13)
A14: Tema 13 | C14: =IF($B14="","",IF(R14<>"",R14,(B14+INDEX(INTERVALOS,COLUMN()-COLUMN($B$1)))+INDEX(DESPLAZAMIENTO,WEEKDAY(B14+INDEX(INTERVALOS,COLUMN()-COLUMN($B$1)),2)))) | D14: =IF($B14="","",IF(S14<>"",S14,(C14+INDEX(INTERVALOS,COLUMN()-COLUMN($B$1)))+INDEX(DESPLAZAMIENTO,WEEKDAY(C14+INDEX(INTERVALOS,COLUMN()-COLUMN($B$1)),2)))) | E14: =IF($B14="","",IF(T14<>"",T14,(D14+INDEX(INTERVALOS,COLUMN()-COLUMN($B$1)))+INDEX(DESPLAZAMIENTO,WEEKDAY(D14+INDEX(INTERVALOS,COLUMN()-COLUMN($B$1)),2)))) | F14: =IF($B14="","",IF(U14<>"",U14,(E14+INDEX(INTERVALOS,COLUMN()-COLUMN($B$1)))+INDEX(DESPLAZAMIENTO,WEEKDAY(E14+INDEX(INTERVALOS,COLUMN()-COLUMN($B$1)),2)))) | G14: =IF($B14="","",IF(V14<>"",V14,(F14+INDEX(INTERVALOS,COLUMN()-COLUMN($B$1)))+INDEX(DESPLAZAMIENTO,WEEKDAY(F14+INDEX(INTERVALOS,COLUMN()-COLUMN($B$1)),2)))) | H14: =IF($B14="","",IF(W14<>"",W14,(G14+INDEX(INTERVALOS,COLUMN()-COLUMN($B$1)))+INDEX(DESPLAZAMIENTO,WEEKDAY(G14+INDEX(INTERVALOS,COLUMN()-COLUMN($B$1)),2)))) | I14: =IF($B14="","",IF(X14<>"",X14,(H14+INDEX(INTERVALOS,COLUMN()-COLUMN($B$1)))+INDEX(DESPLAZAMIENTO,WEEKDAY(H14+INDEX(INTERVALOS,COLUMN()-COLUMN($B$1)),2)))) | J14: =IF($B14="","",IF(Y14<>"",Y14,(I14+INDEX(INTERVALOS,COLUMN()-COLUMN($B$1)))+INDEX(DESPLAZAMIENTO,WEEKDAY(I14+INDEX(INTERVALOS,COLUMN()-COLUMN($B$1)),2)))) | K14: =IF($B14="","",IF(Z14<>"",Z14,(J14+INDEX(INTERVALOS,COLUMN()-COLUMN($B$1)))+INDEX(DESPLAZAMIENTO,WEEKDAY(J14+INDEX(INTERVALOS,COLUMN()-COLUMN($B$1)),2)))) | M14: 90 | AP14: 13 | AQ14: =IF($AN$3="","",$AN$3+(AP14-1)*DIAS_POR_SEMANA) | AR14: =IF(AQ14="","",AQ14+DIAS_POR_SEMANA-1) | AS14: =IF(AQ14="",0,SUMPRODUCT(($AB$2:$AK$41=ESTADO_EXITO)*($AZ$2:$BI$41>=AQ14)*($AZ$2:$BI$41<=AR14))) | AT14: =IF(AQ14="",0,SUMPRODUCT(($AB$2:$AK$41=ESTADO_FALLO)*($AZ$2:$BI$41>=AQ14)*($AZ$2:$BI$41<=AR14))) | AU14: =IF(AS14+AT14=0,"",AS14/(AS14+AT14)) | AV14: =AS14+AT14 | AW14: =SUM($AV$2:AV14) | AX14: =IF(COUNTIFS(AU12:AU14,">=0")=0,"",SUM(AU12:AU14)/COUNTIFS(AU12:AU14,">=0")) | AZ14: =IF(B14="",0,B14) | BA14: =IF(C14="",0,C14) | BB14: =IF(D14="",0,D14) | BC14: =IF(E14="",0,E14) | BD14: =IF(F14="",0,F14) | BE14: =IF(G14="",0,G14) | BF14: =IF(H14="",0,H14) | BG14: =IF(I14="",0,I14) | ... BI14: =IF(K14="",0,K14)
A15: Tema 14 | C15: =IF($B15="","",IF(R15<>"",R15,(B15+INDEX(INTERVALOS,COLUMN()-COLUMN($B$1)))+INDEX(DESPLAZAMIENTO,WEEKDAY(B15+INDEX(INTERVALOS,COLUMN()-COLUMN($B$1)),2)))) | D15: =IF($B15="","",IF(S15<>"",S15,(C15+INDEX(INTERVALOS,COLUMN()-COLUMN($B$1)))+INDEX(DESPLAZAMIENTO,WEEKDAY(C15+INDEX(INTERVALOS,COLUMN()-COLUMN($B$1)),2)))) | E15: =IF($B15="","",IF(T15<>"",T15,(D15+INDEX(INTERVALOS,COLUMN()-COLUMN($B$1)))+INDEX(DESPLAZAMIENTO,WEEKDAY(D15+INDEX(INTERVALOS,COLUMN()-COLUMN($B$1)),2)))) | F15: =IF($B15="","",IF(U15<>"",U15,(E15+INDEX(INTERVALOS,COLUMN()-COLUMN($B$1)))+INDEX(DESPLAZAMIENTO,WEEKDAY(E15+INDEX(INTERVALOS,COLUMN()-COLUMN($B$1)),2)))) | G15: =IF($B15="","",IF(V15<>"",V15,(F15+INDEX(INTERVALOS,COLUMN()-COLUMN($B$1)))+INDEX(DESPLAZAMIENTO,WEEKDAY(F15+INDEX(INTERVALOS,COLUMN()-COLUMN($B$1)),2)))) | H15: =IF($B15="","",IF(W15<>"",W15,(G15+INDEX(INTERVALOS,COLUMN()-COLUMN($B$1)))+INDEX(DESPLAZAMIENTO,WEEKDAY(G15+INDEX(INTERVALOS,COLUMN()-COLUMN($B$1)),2)))) | I15: =IF($B15="","",IF(X15<>"",X15,(H15+INDEX(INTERVALOS,COLUMN()-COLUMN($B$1)))+INDEX(DESPLAZAMIENTO,WEEKDAY(H15+INDEX(INTERVALOS,COLUMN()-COLUMN($B$1)),2)))) | J15: =IF($B15="","",IF(Y15<>"",Y15,(I15+INDEX(INTERVALOS,COLUMN()-COLUMN($B$1)))+INDEX(DESPLAZAMIENTO,WEEKDAY(I15+INDEX(INTERVALOS,COLUMN()-COLUMN($B$1)),2)))) | K15: =IF($B15="","",IF(Z15<>"",Z15,(J15+INDEX(INTERVALOS,COLUMN()-COLUMN($B$1)))+INDEX(DESPLAZAMIENTO,WEEKDAY(J15+INDEX(INTERVALOS,COLUMN()-COLUMN($B$1)),2)))) | M15: 120 | AP15: 14 | AQ15: =IF($AN$3="","",$AN$3+(AP15-1)*DIAS_POR_SEMANA) | AR15: =IF(AQ15="","",AQ15+DIAS_POR_SEMANA-1) | AS15: =IF(AQ15="",0,SUMPRODUCT(($AB$2:$AK$41=ESTADO_EXITO)*($AZ$2:$BI$41>=AQ15)*($AZ$2:$BI$41<=AR15))) | AT15: =IF(AQ15="",0,SUMPRODUCT(($AB$2:$AK$41=ESTADO_FALLO)*($AZ$2:$BI$41>=AQ15)*($AZ$2:$BI$41<=AR15))) | AU15: =IF(AS15+AT15=0,"",AS15/(AS15+AT15)) | AV15: =AS15+AT15 | AW15: =SUM($AV$2:AV15) | AX15: =IF(COUNTIFS(AU13:AU15,">=0")=0,"",SUM(AU13:AU15)/COUNTIFS(AU13:AU15,">=0")) | AZ15: =IF(B15="",0,B15) | BA15: =IF(C15="",0,C15) | BB15: =IF(D15="",0,D15) | BC15: =IF(E15="",0,E15) | BD15: =IF(F15="",0,F15) | BE15: =IF(G15="",0,G15) | BF15: =IF(H15="",0,H15) | BG15: =IF(I15="",0,I15) | ... BI15: =IF(K15="",0,K15)
A16: Tema 15 | C16: =IF($B16="","",IF(R16<>"",R16,(B16+INDEX(INTERVALOS,COLUMN()-COLUMN($B$1)))+INDEX(DESPLAZAMIENTO,WEEKDAY(B16+INDEX(INTERVALOS,COLUMN()-COLUMN($B$1)),2)))) | D16: =IF($B16="","",IF(S16<>"",S16,(C16+INDEX(INTERVALOS,COLUMN()-COLUMN($B$1)))+INDEX(DESPLAZAMIENTO,WEEKDAY(C16+INDEX(INTERVALOS,COLUMN()-COLUMN($B$1)),2)))) | E16: =IF($B16="","",IF(T16<>"",T16,(D16+INDEX(INTERVALOS,COLUMN()-COLUMN($B$1)))+INDEX(DESPLAZAMIENTO,WEEKDAY(D16+INDEX(INTERVALOS,COLUMN()-COLUMN($B$1)),2)))) | F16: =IF($B16="","",IF(U16<>"",U16,(E16+INDEX(INTERVALOS,COLUMN()-COLUMN($B$1)))+INDEX(DESPLAZAMIENTO,WEEKDAY(E16+INDEX(INTERVALOS,COLUMN()-COLUMN($B$1)),2)))) | G16: =IF($B16="","",IF(V16<>"",V16,(F16+INDEX(INTERVALOS,COLUMN()-COLUMN($B$1)))+INDEX(DESPLAZAMIENTO,WEEKDAY(F16+INDEX(INTERVALOS,COLUMN()-COLUMN($B$1)),2)))) | H16: =IF($B16="","",IF(W16<>"",W16,(G16+INDEX(INTERVALOS,COLUMN()-COLUMN($B$1)))+INDEX(DESPLAZAMIENTO,WEEKDAY(G16+INDEX(INTERVALOS,COLUMN()-COLUMN($B$1)),2)))) | I16: =IF($B16="","",IF(X16<>"",X16,(H16+INDEX(INTERVALOS,COLUMN()-COLUMN($B$1)))+INDEX(DESPLAZAMIENTO,WEEKDAY(H16+INDEX(INTERVALOS,COLUMN()-COLUMN($B$1)),2)))) | J16: =IF($B16="","",IF(Y16<>"",Y16,(I16+INDEX(INTERVALOS,COLUMN()-COLUMN($B$1)))+INDEX(DESPLAZAMIENTO,WEEKDAY(I16+INDEX(INTERVALOS,COLUMN()-COLUMN($B$1)),2)))) | K16: =IF($B16="","",IF(Z16<>"",Z16,(J16+INDEX(INTERVALOS,COLUMN()-COLUMN($B$1)))+INDEX(DESPLAZAMIENTO,WEEKDAY(J16+INDEX(INTERVALOS,COLUMN()-COLUMN($B$1)),2)))) | M16: 150 | AP16: 15 | AQ16: =IF($AN$3="","",$AN$3+(AP16-1)*DIAS_POR_SEMANA) | AR16: =IF(AQ16="","",AQ16+DIAS_POR_SEMANA-1) | AS16: =IF(AQ16="",0,SUMPRODUCT(($AB$2:$AK$41=ESTADO_EXITO)*($AZ$2:$BI$41>=AQ16)*($AZ$2:$BI$41<=AR16))) | AT16: =IF(AQ16="",0,SUMPRODUCT(($AB$2:$AK$41=ESTADO_FALLO)*($AZ$2:$BI$41>=AQ16)*($AZ$2:$BI$41<=AR16))) | AU16: =IF(AS16+AT16=0,"",AS16/(AS16+AT16)) | AV16: =AS16+AT16 | AW16: =SUM($AV$2:AV16) | AX16: =IF(COUNTIFS(AU14:AU16,">=0")=0,"",SUM(AU14:AU16)/COUNTIFS(AU14:AU16,">=0")) | AZ16: =IF(B16="",0,B16) | BA16: =IF(C16="",0,C16) | BB16: =IF(D16="",0,D16) | BC16: =IF(E16="",0,E16) | BD16: =IF(F16="",0,F16) | BE16: =IF(G16="",0,G16) | BF16: =IF(H16="",0,H16) | BG16: =IF(I16="",0,I16) | ... BI16: =IF(K16="",0,K16)
A17: Tema 16 | C17: =IF($B17="","",IF(R17<>"",R17,(B17+INDEX(INTERVALOS,COLUMN()-COLUMN($B$1)))+INDEX(DESPLAZAMIENTO,WEEKDAY(B17+INDEX(INTERVALOS,COLUMN()-COLUMN($B$1)),2)))) | D17: =IF($B17="","",IF(S17<>"",S17,(C17+INDEX(INTERVALOS,COLUMN()-COLUMN($B$1)))+INDEX(DESPLAZAMIENTO,WEEKDAY(C17+INDEX(INTERVALOS,COLUMN()-COLUMN($B$1)),2)))) | E17: =IF($B17="","",IF(T17<>"",T17,(D17+INDEX(INTERVALOS,COLUMN()-COLUMN($B$1)))+INDEX(DESPLAZAMIENTO,WEEKDAY(D17+INDEX(INTERVALOS,COLUMN()-COLUMN($B$1)),2)))) | F17: =IF($B17="","",IF(U17<>"",U17,(E17+INDEX(INTERVALOS,COLUMN()-COLUMN($B$1)))+INDEX(DESPLAZAMIENTO,WEEKDAY(E17+INDEX(INTERVALOS,COLUMN()-COLUMN($B$1)),2)))) | G17: =IF($B17="","",IF(V17<>"",V17,(F17+INDEX(INTERVALOS,COLUMN()-COLUMN($B$1)))+INDEX(DESPLAZAMIENTO,WEEKDAY(F17+INDEX(INTERVALOS,COLUMN()-COLUMN($B$1)),2)))) | H17: =IF($B17="","",IF(W17<>"",W17,(G17+INDEX(INTERVALOS,COLUMN()-COLUMN($B$1)))+INDEX(DESPLAZAMIENTO,WEEKDAY(G17+INDEX(INTERVALOS,COLUMN()-COLUMN($B$1)),2)))) | I17: =IF($B17="","",IF(X17<>"",X17,(H17+INDEX(INTERVALOS,COLUMN()-COLUMN($B$1)))+INDEX(DESPLAZAMIENTO,WEEKDAY(H17+INDEX(INTERVALOS,COLUMN()-COLUMN($B$1)),2)))) | J17: =IF($B17="","",IF(Y17<>"",Y17,(I17+INDEX(INTERVALOS,COLUMN()-COLUMN($B$1)))+INDEX(DESPLAZAMIENTO,WEEKDAY(I17+INDEX(INTERVALOS,COLUMN()-COLUMN($B$1)),2)))) | K17: =IF($B17="","",IF(Z17<>"",Z17,(J17+INDEX(INTERVALOS,COLUMN()-COLUMN($B$1)))+INDEX(DESPLAZAMIENTO,WEEKDAY(J17+INDEX(INTERVALOS,COLUMN()-COLUMN($B$1)),2)))) | M17: 180 | AP17: 16 | AQ17: =IF($AN$3="","",$AN$3+(AP17-1)*DIAS_POR_SEMANA) | AR17: =IF(AQ17="","",AQ17+DIAS_POR_SEMANA-1) | AS17: =IF(AQ17="",0,SUMPRODUCT(($AB$2:$AK$41=ESTADO_EXITO)*($AZ$2:$BI$41>=AQ17)*($AZ$2:$BI$41<=AR17))) | AT17: =IF(AQ17="",0,SUMPRODUCT(($AB$2:$AK$41=ESTADO_FALLO)*($AZ$2:$BI$41>=AQ17)*($AZ$2:$BI$41<=AR17))) | AU17: =IF(AS17+AT17=0,"",AS17/(AS17+AT17)) | AV17: =AS17+AT17 | AW17: =SUM($AV$2:AV17) | AX17: =IF(COUNTIFS(AU15:AU17,">=0")=0,"",SUM(AU15:AU17)/COUNTIFS(AU15:AU17,">=0")) | AZ17: =IF(B17="",0,B17) | BA17: =IF(C17="",0,C17) | BB17: =IF(D17="",0,D17) | BC17: =IF(E17="",0,E17) | BD17: =IF(F17="",0,F17) | BE17: =IF(G17="",0,G17) | BF17: =IF(H17="",0,H17) | BG17: =IF(I17="",0,I17) | ... BI17: =IF(K17="",0,K17)
A18: Tema 17 | C18: =IF($B18="","",IF(R18<>"",R18,(B18+INDEX(INTERVALOS,COLUMN()-COLUMN($B$1)))+INDEX(DESPLAZAMIENTO,WEEKDAY(B18+INDEX(INTERVALOS,COLUMN()-COLUMN($B$1)),2)))) | D18: =IF($B18="","",IF(S18<>"",S18,(C18+INDEX(INTERVALOS,COLUMN()-COLUMN($B$1)))+INDEX(DESPLAZAMIENTO,WEEKDAY(C18+INDEX(INTERVALOS,COLUMN()-COLUMN($B$1)),2)))) | E18: =IF($B18="","",IF(T18<>"",T18,(D18+INDEX(INTERVALOS,COLUMN()-COLUMN($B$1)))+INDEX(DESPLAZAMIENTO,WEEKDAY(D18+INDEX(INTERVALOS,COLUMN()-COLUMN($B$1)),2)))) | F18: =IF($B18="","",IF(U18<>"",U18,(E18+INDEX(INTERVALOS,COLUMN()-COLUMN($B$1)))+INDEX(DESPLAZAMIENTO,WEEKDAY(E18+INDEX(INTERVALOS,COLUMN()-COLUMN($B$1)),2)))) | G18: =IF($B18="","",IF(V18<>"",V18,(F18+INDEX(INTERVALOS,COLUMN()-COLUMN($B$1)))+INDEX(DESPLAZAMIENTO,WEEKDAY(F18+INDEX(INTERVALOS,COLUMN()-COLUMN($B$1)),2)))) | H18: =IF($B18="","",IF(W18<>"",W18,(G18+INDEX(INTERVALOS,COLUMN()-COLUMN($B$1)))+INDEX(DESPLAZAMIENTO,WEEKDAY(G18+INDEX(INTERVALOS,COLUMN()-COLUMN($B$1)),2)))) | I18: =IF($B18="","",IF(X18<>"",X18,(H18+INDEX(INTERVALOS,COLUMN()-COLUMN($B$1)))+INDEX(DESPLAZAMIENTO,WEEKDAY(H18+INDEX(INTERVALOS,COLUMN()-COLUMN($B$1)),2)))) | J18: =IF($B18="","",IF(Y18<>"",Y18,(I18+INDEX(INTERVALOS,COLUMN()-COLUMN($B$1)))+INDEX(DESPLAZAMIENTO,WEEKDAY(I18+INDEX(INTERVALOS,COLUMN()-COLUMN($B$1)),2)))) | K18: =IF($B18="","",IF(Z18<>"",Z18,(J18+INDEX(INTERVALOS,COLUMN()-COLUMN($B$1)))+INDEX(DESPLAZAMIENTO,WEEKDAY(J18+INDEX(INTERVALOS,COLUMN()-COLUMN($B$1)),2)))) | AP18: 17 | AQ18: =IF($AN$3="","",$AN$3+(AP18-1)*DIAS_POR_SEMANA) | AR18: =IF(AQ18="","",AQ18+DIAS_POR_SEMANA-1) | AS18: =IF(AQ18="",0,SUMPRODUCT(($AB$2:$AK$41=ESTADO_EXITO)*($AZ$2:$BI$41>=AQ18)*($AZ$2:$BI$41<=AR18))) | AT18: =IF(AQ18="",0,SUMPRODUCT(($AB$2:$AK$41=ESTADO_FALLO)*($AZ$2:$BI$41>=AQ18)*($AZ$2:$BI$41<=AR18))) | AU18: =IF(AS18+AT18=0,"",AS18/(AS18+AT18)) | AV18: =AS18+AT18 | AW18: =SUM($AV$2:AV18) | AX18: =IF(COUNTIFS(AU16:AU18,">=0")=0,"",SUM(AU16:AU18)/COUNTIFS(AU16:AU18,">=0")) | AZ18: =IF(B18="",0,B18) | BA18: =IF(C18="",0,C18) | BB18: =IF(D18="",0,D18) | BC18: =IF(E18="",0,E18) | BD18: =IF(F18="",0,F18) | BE18: =IF(G18="",0,G18) | BF18: =IF(H18="",0,H18) | BG18: =IF(I18="",0,I18) | ... BI18: =IF(K18="",0,K18)
A19: Tema 18 | C19: =IF($B19="","",IF(R19<>"",R19,(B19+INDEX(INTERVALOS,COLUMN()-COLUMN($B$1)))+INDEX(DESPLAZAMIENTO,WEEKDAY(B19+INDEX(INTERVALOS,COLUMN()-COLUMN($B$1)),2)))) | D19: =IF($B19="","",IF(S19<>"",S19,(C19+INDEX(INTERVALOS,COLUMN()-COLUMN($B$1)))+INDEX(DESPLAZAMIENTO,WEEKDAY(C19+INDEX(INTERVALOS,COLUMN()-COLUMN($B$1)),2)))) | E19: =IF($B19="","",IF(T19<>"",T19,(D19+INDEX(INTERVALOS,COLUMN()-COLUMN($B$1)))+INDEX(DESPLAZAMIENTO,WEEKDAY(D19+INDEX(INTERVALOS,COLUMN()-COLUMN($B$1)),2)))) | F19: =IF($B19="","",IF(U19<>"",U19,(E19+INDEX(INTERVALOS,COLUMN()-COLUMN($B$1)))+INDEX(DESPLAZAMIENTO,WEEKDAY(E19+INDEX(INTERVALOS,COLUMN()-COLUMN($B$1)),2)))) | G19: =IF($B19="","",IF(V19<>"",V19,(F19+INDEX(INTERVALOS,COLUMN()-COLUMN($B$1)))+INDEX(DESPLAZAMIENTO,WEEKDAY(F19+INDEX(INTERVALOS,COLUMN()-COLUMN($B$1)),2)))) | H19: =IF($B19="","",IF(W19<>"",W19,(G19+INDEX(INTERVALOS,COLUMN()-COLUMN($B$1)))+INDEX(DESPLAZAMIENTO,WEEKDAY(G19+INDEX(INTERVALOS,COLUMN()-COLUMN($B$1)),2)))) | I19: =IF($B19="","",IF(X19<>"",X19,(H19+INDEX(INTERVALOS,COLUMN()-COLUMN($B$1)))+INDEX(DESPLAZAMIENTO,WEEKDAY(H19+INDEX(INTERVALOS,COLUMN()-COLUMN($B$1)),2)))) | J19: =IF($B19="","",IF(Y19<>"",Y19,(I19+INDEX(INTERVALOS,COLUMN()-COLUMN($B$1)))+INDEX(DESPLAZAMIENTO,WEEKDAY(I19+INDEX(INTERVALOS,COLUMN()-COLUMN($B$1)),2)))) | K19: =IF($B19="","",IF(Z19<>"",Z19,(J19+INDEX(INTERVALOS,COLUMN()-COLUMN($B$1)))+INDEX(DESPLAZAMIENTO,WEEKDAY(J19+INDEX(INTERVALOS,COLUMN()-COLUMN($B$1)),2)))) | AP19: 18 | AQ19: =IF($AN$3="","",$AN$3+(AP19-1)*DIAS_POR_SEMANA) | AR19: =IF(AQ19="","",AQ19+DIAS_POR_SEMANA-1) | AS19: =IF(AQ19="",0,SUMPRODUCT(($AB$2:$AK$41=ESTADO_EXITO)*($AZ$2:$BI$41>=AQ19)*($AZ$2:$BI$41<=AR19))) | AT19: =IF(AQ19="",0,SUMPRODUCT(($AB$2:$AK$41=ESTADO_FALLO)*($AZ$2:$BI$41>=AQ19)*($AZ$2:$BI$41<=AR19))) | AU19: =IF(AS19+AT19=0,"",AS19/(AS19+AT19)) | AV19: =AS19+AT19 | AW19: =SUM($AV$2:AV19) | AX19: =IF(COUNTIFS(AU17:AU19,">=0")=0,"",SUM(AU17:AU19)/COUNTIFS(AU17:AU19,">=0")) | AZ19: =IF(B19="",0,B19) | BA19: =IF(C19="",0,C19) | BB19: =IF(D19="",0,D19) | BC19: =IF(E19="",0,E19) | BD19: =IF(F19="",0,F19) | BE19: =IF(G19="",0,G19) | BF19: =IF(H19="",0,H19) | BG19: =IF(I19="",0,I19) | ... BI19: =IF(K19="",0,K19)
A20: Tema 19 | C20: =IF($B20="","",IF(R20<>"",R20,(B20+INDEX(INTERVALOS,COLUMN()-COLUMN($B$1)))+INDEX(DESPLAZAMIENTO,WEEKDAY(B20+INDEX(INTERVALOS,COLUMN()-COLUMN($B$1)),2)))) | D20: =IF($B20="","",IF(S20<>"",S20,(C20+INDEX(INTERVALOS,COLUMN()-COLUMN($B$1)))+INDEX(DESPLAZAMIENTO,WEEKDAY(C20+INDEX(INTERVALOS,COLUMN()-COLUMN($B$1)),2)))) | E20: =IF($B20="","",IF(T20<>"",T20,(D20+INDEX(INTERVALOS,COLUMN()-COLUMN($B$1)))+INDEX(DESPLAZAMIENTO,WEEKDAY(D20+INDEX(INTERVALOS,COLUMN()-COLUMN($B$1)),2)))) | F20: =IF($B20="","",IF(U20<>"",U20,(E20+INDEX(INTERVALOS,COLUMN()-COLUMN($B$1)))+INDEX(DESPLAZAMIENTO,WEEKDAY(E20+INDEX(INTERVALOS,COLUMN()-COLUMN($B$1)),2)))) | G20: =IF($B20="","",IF(V20<>"",V20,(F20+INDEX(INTERVALOS,COLUMN()-COLUMN($B$1)))+INDEX(DESPLAZAMIENTO,WEEKDAY(F20+INDEX(INTERVALOS,COLUMN()-COLUMN($B$1)),2)))) | H20: =IF($B20="","",IF(W20<>"",W20,(G20+INDEX(INTERVALOS,COLUMN()-COLUMN($B$1)))+INDEX(DESPLAZAMIENTO,WEEKDAY(G20+INDEX(INTERVALOS,COLUMN()-COLUMN($B$1)),2)))) | I20: =IF($B20="","",IF(X20<>"",X20,(H20+INDEX(INTERVALOS,COLUMN()-COLUMN($B$1)))+INDEX(DESPLAZAMIENTO,WEEKDAY(H20+INDEX(INTERVALOS,COLUMN()-COLUMN($B$1)),2)))) | J20: =IF($B20="","",IF(Y20<>"",Y20,(I20+INDEX(INTERVALOS,COLUMN()-COLUMN($B$1)))+INDEX(DESPLAZAMIENTO,WEEKDAY(I20+INDEX(INTERVALOS,COLUMN()-COLUMN($B$1)),2)))) | K20: =IF($B20="","",IF(Z20<>"",Z20,(J20+INDEX(INTERVALOS,COLUMN()-COLUMN($B$1)))+INDEX(DESPLAZAMIENTO,WEEKDAY(J20+INDEX(INTERVALOS,COLUMN()-COLUMN($B$1)),2)))) | AP20: 19 | AQ20: =IF($AN$3="","",$AN$3+(AP20-1)*DIAS_POR_SEMANA) | AR20: =IF(AQ20="","",AQ20+DIAS_POR_SEMANA-1) | AS20: =IF(AQ20="",0,SUMPRODUCT(($AB$2:$AK$41=ESTADO_EXITO)*($AZ$2:$BI$41>=AQ20)*($AZ$2:$BI$41<=AR20))) | AT20: =IF(AQ20="",0,SUMPRODUCT(($AB$2:$AK$41=ESTADO_FALLO)*($AZ$2:$BI$41>=AQ20)*($AZ$2:$BI$41<=AR20))) | AU20: =IF(AS20+AT20=0,"",AS20/(AS20+AT20)) | AV20: =AS20+AT20 | AW20: =SUM($AV$2:AV20) | AX20: =IF(COUNTIFS(AU18:AU20,">=0")=0,"",SUM(AU18:AU20)/COUNTIFS(AU18:AU20,">=0")) | AZ20: =IF(B20="",0,B20) | BA20: =IF(C20="",0,C20) | BB20: =IF(D20="",0,D20) | BC20: =IF(E20="",0,E20) | BD20: =IF(F20="",0,F20) | BE20: =IF(G20="",0,G20) | BF20: =IF(H20="",0,H20) | BG20: =IF(I20="",0,I20) | ... BI20: =IF(K20="",0,K20)
A21: Tema 20 | C21: =IF($B21="","",IF(R21<>"",R21,(B21+INDEX(INTERVALOS,COLUMN()-COLUMN($B$1)))+INDEX(DESPLAZAMIENTO,WEEKDAY(B21+INDEX(INTERVALOS,COLUMN()-COLUMN($B$1)),2)))) | D21: =IF($B21="","",IF(S21<>"",S21,(C21+INDEX(INTERVALOS,COLUMN()-COLUMN($B$1)))+INDEX(DESPLAZAMIENTO,WEEKDAY(C21+INDEX(INTERVALOS,COLUMN()-COLUMN($B$1)),2)))) | E21: =IF($B21="","",IF(T21<>"",T21,(D21+INDEX(INTERVALOS,COLUMN()-COLUMN($B$1)))+INDEX(DESPLAZAMIENTO,WEEKDAY(D21+INDEX(INTERVALOS,COLUMN()-COLUMN($B$1)),2)))) | F21: =IF($B21="","",IF(U21<>"",U21,(E21+INDEX(INTERVALOS,COLUMN()-COLUMN($B$1)))+INDEX(DESPLAZAMIENTO,WEEKDAY(E21+INDEX(INTERVALOS,COLUMN()-COLUMN($B$1)),2)))) | G21: =IF($B21="","",IF(V21<>"",V21,(F21+INDEX(INTERVALOS,COLUMN()-COLUMN($B$1)))+INDEX(DESPLAZAMIENTO,WEEKDAY(F21+INDEX(INTERVALOS,COLUMN()-COLUMN($B$1)),2)))) | H21: =IF($B21="","",IF(W21<>"",W21,(G21+INDEX(INTERVALOS,COLUMN()-COLUMN($B$1)))+INDEX(DESPLAZAMIENTO,WEEKDAY(G21+INDEX(INTERVALOS,COLUMN()-COLUMN($B$1)),2)))) | I21: =IF($B21="","",IF(X21<>"",X21,(H21+INDEX(INTERVALOS,COLUMN()-COLUMN($B$1)))+INDEX(DESPLAZAMIENTO,WEEKDAY(H21+INDEX(INTERVALOS,COLUMN()-COLUMN($B$1)),2)))) | J21: =IF($B21="","",IF(Y21<>"",Y21,(I21+INDEX(INTERVALOS,COLUMN()-COLUMN($B$1)))+INDEX(DESPLAZAMIENTO,WEEKDAY(I21+INDEX(INTERVALOS,COLUMN()-COLUMN($B$1)),2)))) | K21: =IF($B21="","",IF(Z21<>"",Z21,(J21+INDEX(INTERVALOS,COLUMN()-COLUMN($B$1)))+INDEX(DESPLAZAMIENTO,WEEKDAY(J21+INDEX(INTERVALOS,COLUMN()-COLUMN($B$1)),2)))) | AP21: 20 | AQ21: =IF($AN$3="","",$AN$3+(AP21-1)*DIAS_POR_SEMANA) | AR21: =IF(AQ21="","",AQ21+DIAS_POR_SEMANA-1) | AS21: =IF(AQ21="",0,SUMPRODUCT(($AB$2:$AK$41=ESTADO_EXITO)*($AZ$2:$BI$41>=AQ21)*($AZ$2:$BI$41<=AR21))) | AT21: =IF(AQ21="",0,SUMPRODUCT(($AB$2:$AK$41=ESTADO_FALLO)*($AZ$2:$BI$41>=AQ21)*($AZ$2:$BI$41<=AR21))) | AU21: =IF(AS21+AT21=0,"",AS21/(AS21+AT21)) | AV21: =AS21+AT21 | AW21: =SUM($AV$2:AV21) | AX21: =IF(COUNTIFS(AU19:AU21,">=0")=0,"",SUM(AU19:AU21)/COUNTIFS(AU19:AU21,">=0")) | AZ21: =IF(B21="",0,B21) | BA21: =IF(C21="",0,C21) | BB21: =IF(D21="",0,D21) | BC21: =IF(E21="",0,E21) | BD21: =IF(F21="",0,F21) | BE21: =IF(G21="",0,G21) | BF21: =IF(H21="",0,H21) | BG21: =IF(I21="",0,I21) | ... BI21: =IF(K21="",0,K21)
A22: Tema 21 | C22: =IF($B22="","",IF(R22<>"",R22,(B22+INDEX(INTERVALOS,COLUMN()-COLUMN($B$1)))+INDEX(DESPLAZAMIENTO,WEEKDAY(B22+INDEX(INTERVALOS,COLUMN()-COLUMN($B$1)),2)))) | D22: =IF($B22="","",IF(S22<>"",S22,(C22+INDEX(INTERVALOS,COLUMN()-COLUMN($B$1)))+INDEX(DESPLAZAMIENTO,WEEKDAY(C22+INDEX(INTERVALOS,COLUMN()-COLUMN($B$1)),2)))) | E22: =IF($B22="","",IF(T22<>"",T22,(D22+INDEX(INTERVALOS,COLUMN()-COLUMN($B$1)))+INDEX(DESPLAZAMIENTO,WEEKDAY(D22+INDEX(INTERVALOS,COLUMN()-COLUMN($B$1)),2)))) | F22: =IF($B22="","",IF(U22<>"",U22,(E22+INDEX(INTERVALOS,COLUMN()-COLUMN($B$1)))+INDEX(DESPLAZAMIENTO,WEEKDAY(E22+INDEX(INTERVALOS,COLUMN()-COLUMN($B$1)),2)))) | G22: =IF($B22="","",IF(V22<>"",V22,(F22+INDEX(INTERVALOS,COLUMN()-COLUMN($B$1)))+INDEX(DESPLAZAMIENTO,WEEKDAY(F22+INDEX(INTERVALOS,COLUMN()-COLUMN($B$1)),2)))) | H22: =IF($B22="","",IF(W22<>"",W22,(G22+INDEX(INTERVALOS,COLUMN()-COLUMN($B$1)))+INDEX(DESPLAZAMIENTO,WEEKDAY(G22+INDEX(INTERVALOS,COLUMN()-COLUMN($B$1)),2)))) | I22: =IF($B22="","",IF(X22<>"",X22,(H22+INDEX(INTERVALOS,COLUMN()-COLUMN($B$1)))+INDEX(DESPLAZAMIENTO,WEEKDAY(H22+INDEX(INTERVALOS,COLUMN()-COLUMN($B$1)),2)))) | J22: =IF($B22="","",IF(Y22<>"",Y22,(I22+INDEX(INTERVALOS,COLUMN()-COLUMN($B$1)))+INDEX(DESPLAZAMIENTO,WEEKDAY(I22+INDEX(INTERVALOS,COLUMN()-COLUMN($B$1)),2)))) | K22: =IF($B22="","",IF(Z22<>"",Z22,(J22+INDEX(INTERVALOS,COLUMN()-COLUMN($B$1)))+INDEX(DESPLAZAMIENTO,WEEKDAY(J22+INDEX(INTERVALOS,COLUMN()-COLUMN($B$1)),2)))) | AP22: 21 | AQ22: =IF($AN$3="","",$AN$3+(AP22-1)*DIAS_POR_SEMANA) | AR22: =IF(AQ22="","",AQ22+DIAS_POR_SEMANA-1) | AS22: =IF(AQ22="",0,SUMPRODUCT(($AB$2:$AK$41=ESTADO_EXITO)*($AZ$2:$BI$41>=AQ22)*($AZ$2:$BI$41<=AR22))) | AT22: =IF(AQ22="",0,SUMPRODUCT(($AB$2:$AK$41=ESTADO_FALLO)*($AZ$2:$BI$41>=AQ22)*($AZ$2:$BI$41<=AR22))) | AU22: =IF(AS22+AT22=0,"",AS22/(AS22+AT22)) | AV22: =AS22+AT22 | AW22: =SUM($AV$2:AV22) | AX22: =IF(COUNTIFS(AU20:AU22,">=0")=0,"",SUM(AU20:AU22)/COUNTIFS(AU20:AU22,">=0")) | AZ22: =IF(B22="",0,B22) | BA22: =IF(C22="",0,C22) | BB22: =IF(D22="",0,D22) | BC22: =IF(E22="",0,E22) | BD22: =IF(F22="",0,F22) | BE22: =IF(G22="",0,G22) | BF22: =IF(H22="",0,H22) | BG22: =IF(I22="",0,I22) | ... BI22: =IF(K22="",0,K22)
A23: Tema 22 | C23: =IF($B23="","",IF(R23<>"",R23,(B23+INDEX(INTERVALOS,COLUMN()-COLUMN($B$1)))+INDEX(DESPLAZAMIENTO,WEEKDAY(B23+INDEX(INTERVALOS,COLUMN()-COLUMN($B$1)),2)))) | D23: =IF($B23="","",IF(S23<>"",S23,(C23+INDEX(INTERVALOS,COLUMN()-COLUMN($B$1)))+INDEX(DESPLAZAMIENTO,WEEKDAY(C23+INDEX(INTERVALOS,COLUMN()-COLUMN($B$1)),2)))) | E23: =IF($B23="","",IF(T23<>"",T23,(D23+INDEX(INTERVALOS,COLUMN()-COLUMN($B$1)))+INDEX(DESPLAZAMIENTO,WEEKDAY(D23+INDEX(INTERVALOS,COLUMN()-COLUMN($B$1)),2)))) | F23: =IF($B23="","",IF(U23<>"",U23,(E23+INDEX(INTERVALOS,COLUMN()-COLUMN($B$1)))+INDEX(DESPLAZAMIENTO,WEEKDAY(E23+INDEX(INTERVALOS,COLUMN()-COLUMN($B$1)),2)))) | G23: =IF($B23="","",IF(V23<>"",V23,(F23+INDEX(INTERVALOS,COLUMN()-COLUMN($B$1)))+INDEX(DESPLAZAMIENTO,WEEKDAY(F23+INDEX(INTERVALOS,COLUMN()-COLUMN($B$1)),2)))) | H23: =IF($B23="","",IF(W23<>"",W23,(G23+INDEX(INTERVALOS,COLUMN()-COLUMN($B$1)))+INDEX(DESPLAZAMIENTO,WEEKDAY(G23+INDEX(INTERVALOS,COLUMN()-COLUMN($B$1)),2)))) | I23: =IF($B23="","",IF(X23<>"",X23,(H23+INDEX(INTERVALOS,COLUMN()-COLUMN($B$1)))+INDEX(DESPLAZAMIENTO,WEEKDAY(H23+INDEX(INTERVALOS,COLUMN()-COLUMN($B$1)),2)))) | J23: =IF($B23="","",IF(Y23<>"",Y23,(I23+INDEX(INTERVALOS,COLUMN()-COLUMN($B$1)))+INDEX(DESPLAZAMIENTO,WEEKDAY(I23+INDEX(INTERVALOS,COLUMN()-COLUMN($B$1)),2)))) | K23: =IF($B23="","",IF(Z23<>"",Z23,(J23+INDEX(INTERVALOS,COLUMN()-COLUMN($B$1)))+INDEX(DESPLAZAMIENTO,WEEKDAY(J23+INDEX(INTERVALOS,COLUMN()-COLUMN($B$1)),2)))) | AP23: 22 | AQ23: =IF($AN$3="","",$AN$3+(AP23-1)*DIAS_POR_SEMANA) | AR23: =IF(AQ23="","",AQ23+DIAS_POR_SEMANA-1) | AS23: =IF(AQ23="",0,SUMPRODUCT(($AB$2:$AK$41=ESTADO_EXITO)*($AZ$2:$BI$41>=AQ23)*($AZ$2:$BI$41<=AR23))) | AT23: =IF(AQ23="",0,SUMPRODUCT(($AB$2:$AK$41=ESTADO_FALLO)*($AZ$2:$BI$41>=AQ23)*($AZ$2:$BI$41<=AR23))) | AU23: =IF(AS23+AT23=0,"",AS23/(AS23+AT23)) | AV23: =AS23+AT23 | AW23: =SUM($AV$2:AV23) | AX23: =IF(COUNTIFS(AU21:AU23,">=0")=0,"",SUM(AU21:AU23)/COUNTIFS(AU21:AU23,">=0")) | AZ23: =IF(B23="",0,B23) | BA23: =IF(C23="",0,C23) | BB23: =IF(D23="",0,D23) | BC23: =IF(E23="",0,E23) | BD23: =IF(F23="",0,F23) | BE23: =IF(G23="",0,G23) | BF23: =IF(H23="",0,H23) | BG23: =IF(I23="",0,I23) | ... BI23: =IF(K23="",0,K23)
A24: Tema 23 | C24: =IF($B24="","",IF(R24<>"",R24,(B24+INDEX(INTERVALOS,COLUMN()-COLUMN($B$1)))+INDEX(DESPLAZAMIENTO,WEEKDAY(B24+INDEX(INTERVALOS,COLUMN()-COLUMN($B$1)),2)))) | D24: =IF($B24="","",IF(S24<>"",S24,(C24+INDEX(INTERVALOS,COLUMN()-COLUMN($B$1)))+INDEX(DESPLAZAMIENTO,WEEKDAY(C24+INDEX(INTERVALOS,COLUMN()-COLUMN($B$1)),2)))) | E24: =IF($B24="","",IF(T24<>"",T24,(D24+INDEX(INTERVALOS,COLUMN()-COLUMN($B$1)))+INDEX(DESPLAZAMIENTO,WEEKDAY(D24+INDEX(INTERVALOS,COLUMN()-COLUMN($B$1)),2)))) | F24: =IF($B24="","",IF(U24<>"",U24,(E24+INDEX(INTERVALOS,COLUMN()-COLUMN($B$1)))+INDEX(DESPLAZAMIENTO,WEEKDAY(E24+INDEX(INTERVALOS,COLUMN()-COLUMN($B$1)),2)))) | G24: =IF($B24="","",IF(V24<>"",V24,(F24+INDEX(INTERVALOS,COLUMN()-COLUMN($B$1)))+INDEX(DESPLAZAMIENTO,WEEKDAY(F24+INDEX(INTERVALOS,COLUMN()-COLUMN($B$1)),2)))) | H24: =IF($B24="","",IF(W24<>"",W24,(G24+INDEX(INTERVALOS,COLUMN()-COLUMN($B$1)))+INDEX(DESPLAZAMIENTO,WEEKDAY(G24+INDEX(INTERVALOS,COLUMN()-COLUMN($B$1)),2)))) | I24: =IF($B24="","",IF(X24<>"",X24,(H24+INDEX(INTERVALOS,COLUMN()-COLUMN($B$1)))+INDEX(DESPLAZAMIENTO,WEEKDAY(H24+INDEX(INTERVALOS,COLUMN()-COLUMN($B$1)),2)))) | J24: =IF($B24="","",IF(Y24<>"",Y24,(I24+INDEX(INTERVALOS,COLUMN()-COLUMN($B$1)))+INDEX(DESPLAZAMIENTO,WEEKDAY(I24+INDEX(INTERVALOS,COLUMN()-COLUMN($B$1)),2)))) | K24: =IF($B24="","",IF(Z24<>"",Z24,(J24+INDEX(INTERVALOS,COLUMN()-COLUMN($B$1)))+INDEX(DESPLAZAMIENTO,WEEKDAY(J24+INDEX(INTERVALOS,COLUMN()-COLUMN($B$1)),2)))) | AP24: 23 | AQ24: =IF($AN$3="","",$AN$3+(AP24-1)*DIAS_POR_SEMANA) | AR24: =IF(AQ24="","",AQ24+DIAS_POR_SEMANA-1) | AS24: =IF(AQ24="",0,SUMPRODUCT(($AB$2:$AK$41=ESTADO_EXITO)*($AZ$2:$BI$41>=AQ24)*($AZ$2:$BI$41<=AR24))) | AT24: =IF(AQ24="",0,SUMPRODUCT(($AB$2:$AK$41=ESTADO_FALLO)*($AZ$2:$BI$41>=AQ24)*($AZ$2:$BI$41<=AR24))) | AU24: =IF(AS24+AT24=0,"",AS24/(AS24+AT24)) | AV24: =AS24+AT24 | AW24: =SUM($AV$2:AV24) | AX24: =IF(COUNTIFS(AU22:AU24,">=0")=0,"",SUM(AU22:AU24)/COUNTIFS(AU22:AU24,">=0")) | AZ24: =IF(B24="",0,B24) | BA24: =IF(C24="",0,C24) | BB24: =IF(D24="",0,D24) | BC24: =IF(E24="",0,E24) | BD24: =IF(F24="",0,F24) | BE24: =IF(G24="",0,G24) | BF24: =IF(H24="",0,H24) | BG24: =IF(I24="",0,I24) | ... BI24: =IF(K24="",0,K24)
